Workbook

Sheet Navigation
B1: 🏢 LIFE OS ENTERPRISES — MASTER DASHBOARD
B4: ="📅 " & TEXT(TODAY(),"dddd, dd mmm yyyy") & " | ⏰ " & TEXT(NOW(),"hh:mm AM/PM") & " | 📊 61 Sheets | 🔥 12 Day Streak | ⭐ A+" -> 📅 Friday, 09 Oct 2026 | ⏰ 01:28 AM | 📊 61 Sheets | 🔥 12 Day Streak | ⭐ A+
B6: 🔍 QUICK SEARCH — Jump to any sheet
G7: =HYPERLINK("#'"&B7&"'!A1"," GO ▶") -> GO ▶
A10: 📚 ALL SECTIONS — Click any button below
A11: 📅 Planning Sheet
B12: 1. WEEKLY PLANNER | I12: 2. COLLEGE & LEARNING | P12: 3. FOOD & NUTRITION
B13: 🎨 Weekly Dashboard | I13: 🎓 CLO College | P13: 🍽️ Weekly Meal Plan
B14: 📅 Weekly Schedule | I14: 📋 Task Mapping | P14: 🛒 Grocery List
B15: ✅ Habit Tracker | I15: 📊 Progress Tracker | P15: 💧 Water & Health
B16: 🎯 Task Priorities | I16: ⏰ Time Blocks | P16: 🔥 Calorie Tracker
B17: 📝 Weekly Review | I17: 🎨 Color Legend | P17: 👨‍🍳 Meal Prep
I18: 🎓 Amity College | P18: 📖 Recipe Collection
I19: 📘 CKO Knowledge
I20: 🌐 CLO2 Language
I21: 🛠️ CTO Skill Dev
I22: 💼 COO Operations
I23: 🎤 CPO Voice
B26: 4. WEIGHT GAIN DIET | I26: 5. CEO MASTER | P26: 6. DIARY
B27: 💪 Weight Gain Meals | I27: 👑 CEO Dashboard | P27: 📔 Daily Diary
B28: 📊 Calorie & Protein | I28: 🎯 Skills Tracker | P28: 📅 Weekly Diary
B29: ⚖️ Weight Tracker | I29: ⏰ Daily Schedule | P29: 📝 Notes
B30: 🥤 Supplements | I30: 📅 52-Week Plan | P30: 🙏 Gratitude Journal
B31: 🏋️ Workout Diet | I31: 📚 CEO Books
I32: 📝 CEO Journal
I33: 🧠 CEO Mindset
B40: 7. FINANCIAL | I40: 8. MONTHLY SYSTEM | P40: 9. REVISION SYSTEM
B41: 💰 Financial Dashboard | I41: 📊 Monthly Dashboard | P41: 📚 Revision Schedule
B42: 💵 Income Tracker | I42: 📅 Daily Tracker | P42: ✅ Revision Tracker
B43: 💳 Expense Tracker | I43: 🎯 Monthly Goals | P43: 📊 Subject Progress
B44: 🏦 Loan Manager | I44: 🔥 Monthly Habits | P44: 🧠 Techniques
B45: ✅ Daily Checklist | P45: 📝 Revision Log
B46: 🏪 Hatiya Market
B54: 10. YEARLY SYSTEM | I54: 11. SETTINGS
B55: 📅 Year Dashboard | I55: ⚙
B56: 📆 Monthly Tracker | I56: S
B57: 🎯 Yearly Goals
B58: 🌟 Yearly Review
B59: 🔥 Yearly Habits
B60: ="🏢 Life OS Enterprises | CEO: YOU | Build: " & TEXT(NOW(),"dd-mmm-yyyy hh:mm") & " | 61 Sheets | v5.0 SUPER" -> 🏢 Life OS Enterprises | CEO: YOU | Build: 09-Oct-2026 01:28 | 61 Sheets | v5.0 SUPER
...

Sheet Weekly_Dashboard
A1: ←
A3: 📊 WEEKLY OVERVIEW
A5: 📋 Total Tasks | B5: 0
A6: ✅ Completed | B6: 0
A7: 📊 Progress | B7: 0
A8: 🎯 Habits Done | B8: 0/98

Sheet Weekly_Schedule
A1: ←
A3: 📅 WEEKLY SCHEDULE — 30 MIN INTERVALS
A5: TIME | B5: MON | C5: TUE | D5: WED | E5: THU | F5: FRI | G5: SAT | H5: SUN | I5: NOTES | J5: TOPIC | K5: FOLDER | L5: ✓
A6: 0.25 | B6: 🌅 Wake | C6: 🌅 Wake | D6: 🌅 Wake | E6: 🌅 Wake | F6: 🌅 Wake | G6: 🌅 Wake | H6: 🌅 Wake | L6: ☐
A7: 0.27083333 | B7: 🎤 Voice | C7: 🎤 Voice | D7: 🎤 Voice | E7: 🎤 Voice | F7: 🎤 Voice | G7: 🎤 Voice | H7: 🎤 Voice | L7: ☐
A8: 0.29166667 | B8: 💪 Exercise | C8: 💪 Exercise | D8: 💪 Exercise | E8: 💪 Exercise | F8: 💪 Exercise | G8: 💪 Exercise | H8: 💪 Exercise | L8: ☐
A9: 0.3125 | B9: 📘 Knowledge | C9: 📘 Knowledge | D9: 📘 Knowledge | E9: 📘 Knowledge | F9: 📘 Knowledge | G9: 📘 Knowledge | H9: 📘 Knowledge | L9: ☐
A10: 0.33333333 | B10: 🍳 Breakfast | C10: 🍳 Breakfast | D10: 🍳 Breakfast | E10: 🍳 Breakfast | F10: 🍳 Breakfast | G10: 🍳 Breakfast | H10: 🍳 Breakfast | L10: ☐
A11: 0.35416667 | B11: 🌐 Language | C11: 🌐 Language | D11: 🌐 Language | E11: 🌐 Language | F11: 🌐 Language | G11: 🌐 Language | H11: 🌐 Language | L11: ☐
A12: 0.39583333 | B12: ☕ Break | C12: ☕ Break | D12: ☕ Break | E12: ☕ Break | F12: ☕ Break | G12: ☕ Break | H12: ☕ Break | L12: ☐
A13: 0.41666667 | B13: 🎓 College 1 | C13: 🎓 College 1 | D13: 🎓 College 1 | E13: 🎓 College 1 | F13: 🎓 College 1 | G13: 🎓 College 1 | H13: 🎓 College 1 | L13: ☐
A14: 0.47916667 | B14: ⚡ Deep Work | C14: ⚡ Deep Work | D14: ⚡ Deep Work | E14: ⚡ Deep Work | F14: ⚡ Deep Work | G14: ⚡ Deep Work | H14: ⚡ Deep Work | L14: ☐
A15: 0.5 | B15: 🍽️ Lunch | C15: 🍽️ Lunch | D15: 🍽️ Lunch | E15: 🍽️ Lunch | F15: 🍽️ Lunch | G15: 🍽️ Lunch | H15: 🍽️ Lunch | L15: ☐
A16: 0.54166667 | B16: 🔄 Revision | C16: 🔄 Revision | D16: 🔄 Revision | E16: 🔄 Revision | F16: 🔄 Revision | G16: 🔄 Revision | H16: 🔄 Revision | L16: ☐
A17: 0.5625 | B17: 🎓 College 2 | C17: 🎓 College 2 | D17: 🎓 College 2 | E17: 🎓 College 2 | F17: 🎓 College 2 | G17: 🎓 College 2 | H17: 🎓 College 2 | L17: ☐
... A28: 0.91666667 | B28: 🛏️ Sleep | C28: 🛏️ Sleep | D28: 🛏️ Sleep | E28: 🛏️ Sleep | F28: 🛏️ Sleep | G28: 🛏️ Sleep | H28: 🛏️ Sleep | L28: ☐

Sheet Habit_Tracker
A1: ←
A2: 💡 Click cell → dropdown → Select ✅ or ☐
A3: HABIT | B3: MON | C3: TUE | D3: WED | E3: THU | F3: FRI | G3: SAT | H3: SUN | I3: DONE | J3: % | K3: STATUS
A4: 🌅 Wake at 6 AM | B4: ☐ | C4: ☐ | D4: ☐ | E4: ☐ | F4: ☐ | G4: ☐ | H4: ☐ | I4: =COUNTIF(B4:H4,"✅") -> 0 | J4: =IFERROR(I4/7,0) -> 0 | K4: =IF(J4>=0.9,"🟢 Excellent",IF(J4>=0.7,"🟡 Good",IF(J4>0,"🔴 Started","⚪ Not Started"))) -> ⚪ Not Started
A5: 🎤 Voice Exercise | B5: ☐ | C5: ☐ | D5: ☐ | E5: ☐ | F5: ☐ | G5: ☐ | H5: ☐ | I5: =COUNTIF(B5:H5,"✅") -> 0 | J5: =IFERROR(I5/7,0) -> 0 | K5: =IF(J5>=0.9,"🟢 Excellent",IF(J5>=0.7,"🟡 Good",IF(J5>0,"🔴 Started","⚪ Not Started"))) -> ⚪ Not Started
A6: 💪 Exercise 30 min | B6: ☐ | C6: ☐ | D6: ☐ | E6: ☐ | F6: ☐ | G6: ☐ | H6: ☐ | I6: =COUNTIF(B6:H6,"✅") -> 0 | J6: =IFERROR(I6/7,0) -> 0 | K6: =IF(J6>=0.9,"🟢 Excellent",IF(J6>=0.7,"🟡 Good",IF(J6>0,"🔴 Started","⚪ Not Started"))) -> ⚪ Not Started
A7: 📘 Knowledge 1 hr | B7: ☐ | C7: ☐ | D7: ☐ | E7: ☐ | F7: ☐ | G7: ☐ | H7: ☐ | I7: =COUNTIF(B7:H7,"✅") -> 0 | J7: =IFERROR(I7/7,0) -> 0 | K7: =IF(J7>=0.9,"🟢 Excellent",IF(J7>=0.7,"🟡 Good",IF(J7>0,"🔴 Started","⚪ Not Started"))) -> ⚪ Not Started
A8: 🌐 Language 1 hr | B8: ☐ | C8: ☐ | D8: ☐ | E8: ☐ | F8: ☐ | G8: ☐ | H8: ☐ | I8: =COUNTIF(B8:H8,"✅") -> 0 | J8: =IFERROR(I8/7,0) -> 0 | K8: =IF(J8>=0.9,"🟢 Excellent",IF(J8>=0.7,"🟡 Good",IF(J8>0,"🔴 Started","⚪ Not Started"))) -> ⚪ Not Started
A9: 🎓 College Study | B9: ☐ | C9: ☐ | D9: ☐ | E9: ☐ | F9: ☐ | G9: ☐ | H9: ☐ | I9: =COUNTIF(B9:H9,"✅") -> 0 | J9: =IFERROR(I9/7,0) -> 0 | K9: =IF(J9>=0.9,"🟢 Excellent",IF(J9>=0.7,"🟡 Good",IF(J9>0,"🔴 Started","⚪ Not Started"))) -> ⚪ Not Started
A10: 🛠️ Skill Practice | B10: ☐ | C10: ☐ | D10: ☐ | E10: ☐ | F10: ☐ | G10: ☐ | H10: ☐ | I10: =COUNTIF(B10:H10,"✅") -> 0 | J10: =IFERROR(I10/7,0) -> 0 | K10: =IF(J10>=0.9,"🟢 Excellent",IF(J10>=0.7,"🟡 Good",IF(J10>0,"🔴 Started","⚪ Not Started"))) -> ⚪ Not Started
A11: 💼 Office Work | B11: ☐ | C11: ☐ | D11: ☐ | E11: ☐ | F11: ☐ | G11: ☐ | H11: ☐ | I11: =COUNTIF(B11:H11,"✅") -> 0 | J11: =IFERROR(I11/7,0) -> 0 | K11: =IF(J11>=0.9,"🟢 Excellent",IF(J11>=0.7,"🟡 Good",IF(J11>0,"🔴 Started","⚪ Not Started"))) -> ⚪ Not Started
A12: 💧 8 Glasses Water | B12: ☐ | C12: ☐ | D12: ☐ | E12: ☐ | F12: ☐ | G12: ☐ | H12: ☐ | I12: =COUNTIF(B12:H12,"✅") -> 0 | J12: =IFERROR(I12/7,0) -> 0 | K12: =IF(J12>=0.9,"🟢 Excellent",IF(J12>=0.7,"🟡 Good",IF(J12>0,"🔴 Started","⚪ Not Started"))) -> ⚪ Not Started
A13: 📝 Journal Writing | B13: ☐ | C13: ☐ | D13: ☐ | E13: ☐ | F13: ☐ | G13: ☐ | H13: ☐ | I13: =COUNTIF(B13:H13,"✅") -> 0 | J13: =IFERROR(I13/7,0) -> 0 | K13: =IF(J13>=0.9,"🟢 Excellent",IF(J13>=0.7,"🟡 Good",IF(J13>0,"🔴 Started","⚪ Not Started"))) -> ⚪ Not Started
A14: 📚 Read 30 min | B14: ☐ | C14: ☐ | D14: ☐ | E14: ☐ | F14: ☐ | G14: ☐ | H14: ☐ | I14: =COUNTIF(B14:H14,"✅") -> 0 | J14: =IFERROR(I14/7,0) -> 0 | K14: =IF(J14>=0.9,"🟢 Excellent",IF(J14>=0.7,"🟡 Good",IF(J14>0,"🔴 Started","⚪ Not Started"))) -> ⚪ Not Started
A15: 🧘 Meditation | B15: ☐ | C15: ☐ | D15: ☐ | E15: ☐ | F15: ☐ | G15: ☐ | H15: ☐ | I15: =COUNTIF(B15:H15,"✅") -> 0 | J15: =IFERROR(I15/7,0) -> 0 | K15: =IF(J15>=0.9,"🟢 Excellent",IF(J15>=0.7,"🟡 Good",IF(J15>0,"🔴 Started","⚪ Not Started"))) -> ⚪ Not Started
... A17: 📵 No Phone after 9 | B17: ☐ | C17: ☐ | D17: ☐ | E17: ☐ | F17: ☐ | G17: ☐ | H17: ☐ | I17: =COUNTIF(B17:H17,"✅") -> 0 | J17: =IFERROR(I17/7,0) -> 0 | K17: =IF(J17>=0.9,"🟢 Excellent",IF(J17>=0.7,"🟡 Good",IF(J17>0,"🔴 Started","⚪ Not Started"))) -> ⚪ Not Started
A18: 📊 DAILY TOTAL | B18: =COUNTIF(B4:B17,"✅") -> 0 | C18: =COUNTIF(C4:C17,"✅") -> 0 | D18: =COUNTIF(D4:D17,"✅") -> 0 | E18: =COUNTIF(E4:E17,"✅") -> 0 | F18: =COUNTIF(F4:F17,"✅") -> 0 | G18: =COUNTIF(G4:G17,"✅") -> 0 | H18: =COUNTIF(H4:H17,"✅") -> 0

Sheet Task_Priorities
A1: ←
A3: 🔴 HIGH PRIORITY | D3: 🟡 MEDIUM PRIORITY | G3: 🟢 LOW PRIORITY
A4: ☐ Task 1: | D4: ☐ Task 1: | G4: ☐ Task 1:
A5: ☐ Task 2: | D5: ☐ Task 2: | G5: ☐ Task 2:
A6: ☐ Task 3: | D6: ☐ Task 3: | G6: ☐ Task 3:
A7: ☐ Task 4: | D7: ☐ Task 4: | G7: ☐ Task 4:
A8: ☐ Task 5: | D8: ☐ Task 5: | G8: ☐ Task 5:
A9: ☐ Task 6: | D9: ☐ Task 6: | G9: ☐ Task 6:
A10: ☐ Task 7: | D10: ☐ Task 7: | G10: ☐ Task 7:
A11: ☐ Task 8: | D11: ☐ Task 8: | G11: ☐ Task 8:
A12: ☐ Task 9: | D12: ☐ Task 9: | G12: ☐ Task 9:
A13: ☐ Task 10: | D13: ☐ Task 10: | G13: ☐ Task 10:
A14: ☐ Task 11: | D14: ☐ Task 11: | G14: ☐ Task 11:
... A18: ☐ Task 15: | D18: ☐ Task 15: | G18: ☐ Task 15:

Sheet Weekly_Review
A1: ←
A3: 🏆 What went well this week?
A4: 📚 What did I learn?
A5: ⚠️ What challenges did I face?
A6: 💡 What could be improved?
A7: 🙏 What am I grateful for?
A8: 🎯 Top 3 priorities for next week?
A9: 📊 Overall week rating (1-10):
A10: 🌟 Biggest win of the week:
A11: 💪 What will I do differently?
A12: 📅 Key dates next week:

Sheet CLO_College
A1: ←
A3: SUBJECT | B3: MON | C3: TUE | D3: WED | E3: THU | F3: FRI | G3: SAT | H3: SUN | I3: %
A4: 1. Business Statistics | B4: ☐ | C4: ☐ | D4: ☐ | E4: ☐ | F4: ☐ | G4: ☐ | H4: ☐ | I4: =IFERROR(COUNTIF(B4:H4,"✅")/7,0) -> 0
A5: 2. Business Communication | B5: ☐ | C5: ☐ | D5: ☐ | E5: ☐ | F5: ☐ | G5: ☐ | H5: ☐ | I5: =IFERROR(COUNTIF(B5:H5,"✅")/7,0) -> 0
A6: 3. Management Foundation | B6: ☐ | C6: ☐ | D6: ☐ | E6: ☐ | F6: ☐ | G6: ☐ | H6: ☐ | I6: =IFERROR(COUNTIF(B6:H6,"✅")/7,0) -> 0
A7: 4. Accounting Fundamentals | B7: ☐ | C7: ☐ | D7: ☐ | E7: ☐ | F7: ☐ | G7: ☐ | H7: ☐ | I7: =IFERROR(COUNTIF(B7:H7,"✅")/7,0) -> 0
A8: 5. Principles of Marketing | B8: ☐ | C8: ☐ | D8: ☐ | E8: ☐ | F8: ☐ | G8: ☐ | H8: ☐ | I8: =IFERROR(COUNTIF(B8:H8,"✅")/7,0) -> 0
A9: 8. Live Class – Business Comm | B9: ☐ | C9: ☐ | D9: ☐ | E9: ☐ | F9: ☐ | G9: ☐ | H9: ☐ | I9: =IFERROR(COUNTIF(B9:H9,"✅")/7,0) -> 0
A10: 7. Free Certificate Course | B10: ☐ | C10: ☐ | D10: ☐ | E10: ☐ | F10: ☐ | G10: ☐ | H10: ☐ | I10: =IFERROR(COUNTIF(B10:H10,"✅")/7,0) -> 0
A11: 6. Student Dev Programme | B11: ☐ | C11: ☐ | D11: ☐ | E11: ☐ | F11: ☐ | G11: ☐ | H11: ☐ | I11: =IFERROR(COUNTIF(B11:H11,"✅")/7,0) -> 0
A12: 9. Business Plan Trailblazers | B12: ☐ | C12: ☐ | D12: ☐ | E12: ☐ | F12: ☐ | G12: ☐ | H12: ☐ | I12: =IFERROR(COUNTIF(B12:H12,"✅")/7,0) -> 0
A13: Study_track Update | B13: ☐ | C13: ☐ | D13: ☐ | E13: ☐ | F13: ☐ | G13: ☐ | H13: ☐ | I13: =IFERROR(COUNTIF(B13:H13,"✅")/7,0) -> 0
A14: 📊 AVERAGE | I14: =IFERROR(AVERAGE(I4:I13),0) -> 0

Sheet Task_Mapping
A1: ←
A3: 🎓 COLLEGE — WEEKLY SUBJECT PLAN
A4: Mon | B4: Business Statistics | C4: 0.41666667 | D4: Chapter + Problems
A5: Mon | B5: Accounting Fundamentals | C5: 0.58333333 | D5: Practice entries
A6: Mon | B6: Management Foundation | C6: 0.79166667 | D6: Case study
A7: Tue | B7: Business Communication | C7: 0.41666667 | D7: Writing practice
A8: Tue | B8: Principles of Marketing | C8: 0.58333333 | D8: Concepts + Examples
A9: Tue | B9: Business Statistics | C9: 0.79166667 | D9: Revision
A10: Wed | B10: Accounting Fundamentals | C10: 0.41666667 | D10: Balance sheet
A11: Wed | B11: Business Statistics | C11: 0.58333333 | D11: Data analysis
A12: Wed | B12: Business Communication | C12: 0.79166667 | D12: Speaking practice
A13: Thu | B13: Management Foundation | C13: 0.41666667 | D13: Theories
A14: Thu | B14: Business Communication | C14: 0.58333333 | D14: Report writing
A15: Thu | B15: Accounting Fundamentals | C15: 0.79166667 | D15: Final accounts
... A21: Sat | B21: Student Dev Programme | C21: 0.79166667 | D21: Activity

Sheet Progress_Tracker
A1: ←
A3: TASK | B3: MON | C3: TUE | D3: WED | E3: THU | F3: FRI | G3: SAT | H3: SUN | I3: %
A4: 🎓 College Study | B4: ☐ | C4: ☐ | D4: ☐ | E4: ☐ | F4: ☐ | G4: ☐ | H4: ☐ | I4: =IFERROR(COUNTIF(B4:H4,"✅")/7,0) -> 0
A5: 📘 Knowledge | B5: ☐ | C5: ☐ | D5: ☐ | E5: ☐ | F5: ☐ | G5: ☐ | H5: ☐ | I5: =IFERROR(COUNTIF(B5:H5,"✅")/7,0) -> 0
A6: 🌐 Language | B6: ☐ | C6: ☐ | D6: ☐ | E6: ☐ | F6: ☐ | G6: ☐ | H6: ☐ | I6: =IFERROR(COUNTIF(B6:H6,"✅")/7,0) -> 0
A7: 🛠️ Skill Dev | B7: ☐ | C7: ☐ | D7: ☐ | E7: ☐ | F7: ☐ | G7: ☐ | H7: ☐ | I7: =IFERROR(COUNTIF(B7:H7,"✅")/7,0) -> 0
A8: 💼 Office Work | B8: ☐ | C8: ☐ | D8: ☐ | E8: ☐ | F8: ☐ | G8: ☐ | H8: ☐ | I8: =IFERROR(COUNTIF(B8:H8,"✅")/7,0) -> 0
A9: ⚡ Advance Block | B9: ☐ | C9: ☐ | D9: ☐ | E9: ☐ | F9: ☐ | G9: ☐ | H9: ☐ | I9: =IFERROR(COUNTIF(B9:H9,"✅")/7,0) -> 0
A10: 🔄 Revision | B10: ☐ | C10: ☐ | D10: ☐ | E10: ☐ | F10: ☐ | G10: ☐ | H10: ☐ | I10: =IFERROR(COUNTIF(B10:H10,"✅")/7,0) -> 0
A11: 📝 Notes | B11: ☐ | C11: ☐ | D11: ☐ | E11: ☐ | F11: ☐ | G11: ☐ | H11: ☐ | I11: =IFERROR(COUNTIF(B11:H11,"✅")/7,0) -> 0

Sheet Time_Blocks
A1: ←
A3: BLOCK | B3: START TIME | C3: END TIME | D3: DURATION | E3: FOCUS
A4: Morning Routine | B4: 0.25 | C4: 0.29166667 | D4: 1 hr | E4: Wake + Exercise
A5: Knowledge Block 1 | B5: 0.29166667 | C5: 0.33333333 | D5: 1 hr | E5: 📘 01_knowledge
A6: Breakfast | B6: 0.33333333 | C6: 0.35416667 | D6: 30 min | E6: —
A7: Language Block 1 | B7: 0.35416667 | C7: 0.39583333 | D7: 1 hr | E7: 🌐 02_languages
A8: Break | B8: 0.39583333 | C8: 0.41666667 | D8: 30 min | E8: —
A9: 🎓 College Block 1 | B9: 0.41666667 | C9: 0.47916667 | D9: 1.5 hr | E9: College Subjects
A10: Advance Block | B10: 0.47916667 | C10: 0.5 | D10: 30 min | E10: ⚡ Deep Work
A11: Lunch | B11: 0.5 | C11: 0.54166667 | D11: 1 hr | E11: —
A12: Rest | B12: 0.54166667 | C12: 0.5625 | D12: 30 min | E12: —
A13: Revision | B13: 0.5625 | C13: 0.58333333 | D13: 30 min | E13: 🔄 All
A14: 🎓 College Block 2 | B14: 0.58333333 | C14: 0.625 | D14: 1 hr | E14: College Subjects
A15: Skill Dev Block 2 | B15: 0.625 | C15: 0.66666667 | D15: 1 hr | E15: 🛠️ 04_skill_dev
... A24: Sleep | B24: 0.91666667 | C24: 0.25 | D24: 8 hr | E24: 🛏️

Sheet Color_Legend
A1: ←
A3: COLOR | B3: BLOCK | C3: FOLDER / FOCUS
A4: 🟫 Brown | B4: 🎓 College | C4: College/University Subjects
A5: 🟦 Blue | B5: 📘 Knowledge | C5: 01_knowledge/
A6: 🟩 Green | B6: 🌐 Language | C6: 02_languages/
A7: 🟧 Orange | B7: 🛠️ Skill Dev | C7: 04_skill_dev/
A8: 🟪 Purple | B8: ⚡ Advance Block | C8: Deep Work / Project
A9: 🟨 Yellow | B9: 💼 Office Work | C9: office work/
A10: ⬜ Grey | B10: ☕ Break / Rest | C10: Recovery
A11: 🟨 Yellow | B11: 🔄 Revision | C11: All folders

Sheet Amity_College
A1: ←
A3: SUBJECT | B3: MON | C3: TUE | D3: WED | E3: THU | F3: FRI | G3: SAT | H3: SUN | I3: %
A4: Business Statistics | B4: ☐ | C4: ☐ | D4: ☐ | E4: ☐ | F4: ☐ | G4: ☐ | H4: ☐ | I4: =IFERROR(COUNTIF(B4:H4,"✅")/7,0) -> 0
A5: Business Communication | B5: ☐ | C5: ☐ | D5: ☐ | E5: ☐ | F5: ☐ | G5: ☐ | H5: ☐ | I5: =IFERROR(COUNTIF(B5:H5,"✅")/7,0) -> 0
A6: Management Foundation | B6: ☐ | C6: ☐ | D6: ☐ | E6: ☐ | F6: ☐ | G6: ☐ | H6: ☐ | I6: =IFERROR(COUNTIF(B6:H6,"✅")/7,0) -> 0
A7: Accounting Fundamentals | B7: ☐ | C7: ☐ | D7: ☐ | E7: ☐ | F7: ☐ | G7: ☐ | H7: ☐ | I7: =IFERROR(COUNTIF(B7:H7,"✅")/7,0) -> 0
A8: Principles of Marketing | B8: ☐ | C8: ☐ | D8: ☐ | E8: ☐ | F8: ☐ | G8: ☐ | H8: ☐ | I8: =IFERROR(COUNTIF(B8:H8,"✅")/7,0) -> 0
B9: ☐ | C9: ☐ | D9: ☐ | E9: ☐ | F9: ☐ | G9: ☐ | H9: ☐ | I9: =IFERROR(COUNTIF(B9:H9,"✅")/7,0) -> 0
B10: ☐ | C10: ☐ | D10: ☐ | E10: ☐ | F10: ☐ | G10: ☐ | H10: ☐ | I10: =IFERROR(COUNTIF(B10:H10,"✅")/7,0) -> 0
B11: ☐ | C11: ☐ | D11: ☐ | E11: ☐ | F11: ☐ | G11: ☐ | H11: ☐ | I11: =IFERROR(COUNTIF(B11:H11,"✅")/7,0) -> 0
B12: ☐ | C12: ☐ | D12: ☐ | E12: ☐ | F12: ☐ | G12: ☐ | H12: ☐ | I12: =IFERROR(COUNTIF(B12:H12,"✅")/7,0) -> 0
B13: ☐ | C13: ☐ | D13: ☐ | E13: ☐ | F13: ☐ | G13: ☐ | H13: ☐ | I13: =IFERROR(COUNTIF(B13:H13,"✅")/7,0) -> 0
B14: ☐ | C14: ☐ | D14: ☐ | E14: ☐ | F14: ☐ | G14: ☐ | H14: ☐ | I14: =IFERROR(COUNTIF(B14:H14,"✅")/7,0) -> 0
B15: ☐ | C15: ☐ | D15: ☐ | E15: ☐ | F15: ☐ | G15: ☐ | H15: ☐ | I15: =IFERROR(COUNTIF(B15:H15,"✅")/7,0) -> 0

Sheet CKO_Knowledge
A1: ←
A3: SUBJECT | B3: MON | C3: TUE | D3: WED | E3: THU | F3: FRI | G3: SAT | H3: SUN | I3: %
A4: 📚 Books | B4: ☐ | C4: ☐ | D4: ☐ | E4: ☐ | F4: ☐ | G4: ☐ | H4: ☐ | I4: =IFERROR(COUNTIF(B4:H4,"✅")/7,0) -> 0
A5: 📰 Articles | B5: ☐ | C5: ☐ | D5: ☐ | E5: ☐ | F5: ☐ | G5: ☐ | H5: ☐ | I5: =IFERROR(COUNTIF(B5:H5,"✅")/7,0) -> 0
A6: 🤖 AI Prompts | B6: ☐ | C6: ☐ | D6: ☐ | E6: ☐ | F6: ☐ | G6: ☐ | H6: ☐ | I6: =IFERROR(COUNTIF(B6:H6,"✅")/7,0) -> 0
A7: 📝 Notes | B7: ☐ | C7: ☐ | D7: ☐ | E7: ☐ | F7: ☐ | G7: ☐ | H7: ☐ | I7: =IFERROR(COUNTIF(B7:H7,"✅")/7,0) -> 0
A8: 🎥 Videos | B8: ☐ | C8: ☐ | D8: ☐ | E8: ☐ | F8: ☐ | G8: ☐ | H8: ☐ | I8: =IFERROR(COUNTIF(B8:H8,"✅")/7,0) -> 0
B9: ☐ | C9: ☐ | D9: ☐ | E9: ☐ | F9: ☐ | G9: ☐ | H9: ☐ | I9: =IFERROR(COUNTIF(B9:H9,"✅")/7,0) -> 0
B10: ☐ | C10: ☐ | D10: ☐ | E10: ☐ | F10: ☐ | G10: ☐ | H10: ☐ | I10: =IFERROR(COUNTIF(B10:H10,"✅")/7,0) -> 0
B11: ☐ | C11: ☐ | D11: ☐ | E11: ☐ | F11: ☐ | G11: ☐ | H11: ☐ | I11: =IFERROR(COUNTIF(B11:H11,"✅")/7,0) -> 0
B12: ☐ | C12: ☐ | D12: ☐ | E12: ☐ | F12: ☐ | G12: ☐ | H12: ☐ | I12: =IFERROR(COUNTIF(B12:H12,"✅")/7,0) -> 0
B13: ☐ | C13: ☐ | D13: ☐ | E13: ☐ | F13: ☐ | G13: ☐ | H13: ☐ | I13: =IFERROR(COUNTIF(B13:H13,"✅")/7,0) -> 0
B14: ☐ | C14: ☐ | D14: ☐ | E14: ☐ | F14: ☐ | G14: ☐ | H14: ☐ | I14: =IFERROR(COUNTIF(B14:H14,"✅")/7,0) -> 0
B15: ☐ | C15: ☐ | D15: ☐ | E15: ☐ | F15: ☐ | G15: ☐ | H15: ☐ | I15: =IFERROR(COUNTIF(B15:H15,"✅")/7,0) -> 0

Sheet CLO2_Language
A1: ←
A3: LANGUAGE | B3: MON | C3: TUE | D3: WED | E3: THU | F3: FRI | G3: SAT | H3: SUN | I3: %
A4: 🇬🇧 English Advanced | B4: ☐ | C4: ☐ | D4: ☐ | E4: ☐ | F4: ☐ | G4: ☐ | H4: ☐ | I4: =IFERROR(COUNTIF(B4:H4,"✅")/7,0) -> 0
A5: 🇯🇵 Japanese | B5: ☐ | C5: ☐ | D5: ☐ | E5: ☐ | F5: ☐ | G5: ☐ | H5: ☐ | I5: =IFERROR(COUNTIF(B5:H5,"✅")/7,0) -> 0
A6: 🇪🇸 Spanish | B6: ☐ | C6: ☐ | D6: ☐ | E6: ☐ | F6: ☐ | G6: ☐ | H6: ☐ | I6: =IFERROR(COUNTIF(B6:H6,"✅")/7,0) -> 0
A7: 🇫🇷 French | B7: ☐ | C7: ☐ | D7: ☐ | E7: ☐ | F7: ☐ | G7: ☐ | H7: ☐ | I7: =IFERROR(COUNTIF(B7:H7,"✅")/7,0) -> 0
A8: 🇩🇪 German | B8: ☐ | C8: ☐ | D8: ☐ | E8: ☐ | F8: ☐ | G8: ☐ | H8: ☐ | I8: =IFERROR(COUNTIF(B8:H8,"✅")/7,0) -> 0
A9: 🇰🇷 Korean | B9: ☐ | C9: ☐ | D9: ☐ | E9: ☐ | F9: ☐ | G9: ☐ | H9: ☐ | I9: =IFERROR(COUNTIF(B9:H9,"✅")/7,0) -> 0
A10: 🇨🇳 Mandarin | B10: ☐ | C10: ☐ | D10: ☐ | E10: ☐ | F10: ☐ | G10: ☐ | H10: ☐ | I10: =IFERROR(COUNTIF(B10:H10,"✅")/7,0) -> 0
B11: ☐ | C11: ☐ | D11: ☐ | E11: ☐ | F11: ☐ | G11: ☐ | H11: ☐ | I11: =IFERROR(COUNTIF(B11:H11,"✅")/7,0) -> 0
B12: ☐ | C12: ☐ | D12: ☐ | E12: ☐ | F12: ☐ | G12: ☐ | H12: ☐ | I12: =IFERROR(COUNTIF(B12:H12,"✅")/7,0) -> 0
B13: ☐ | C13: ☐ | D13: ☐ | E13: ☐ | F13: ☐ | G13: ☐ | H13: ☐ | I13: =IFERROR(COUNTIF(B13:H13,"✅")/7,0) -> 0
B14: ☐ | C14: ☐ | D14: ☐ | E14: ☐ | F14: ☐ | G14: ☐ | H14: ☐ | I14: =IFERROR(COUNTIF(B14:H14,"✅")/7,0) -> 0
B15: ☐ | C15: ☐ | D15: ☐ | E15: ☐ | F15: ☐ | G15: ☐ | H15: ☐ | I15: =IFERROR(COUNTIF(B15:H15,"✅")/7,0) -> 0

Sheet CTO_SkillDev
A1: ←
A3: SKILL | B3: MON | C3: TUE | D3: WED | E3: THU | F3: FRI | G3: SAT | H3: SUN | I3: %
A4: 📊 Excel | B4: ☐ | C4: ☐ | D4: ☐ | E4: ☐ | F4: ☐ | G4: ☐ | H4: ☐ | I4: =IFERROR(COUNTIF(B4:H4,"✅")/7,0) -> 0
A5: 🗄️ SQL | B5: ☐ | C5: ☐ | D5: ☐ | E5: ☐ | F5: ☐ | G5: ☐ | H5: ☐ | I5: =IFERROR(COUNTIF(B5:H5,"✅")/7,0) -> 0
A6: 🐍 Python | B6: ☐ | C6: ☐ | D6: ☐ | E6: ☐ | F6: ☐ | G6: ☐ | H6: ☐ | I6: =IFERROR(COUNTIF(B6:H6,"✅")/7,0) -> 0
A7: 📈 Power BI | B7: ☐ | C7: ☐ | D7: ☐ | E7: ☐ | F7: ☐ | G7: ☐ | H7: ☐ | I7: =IFERROR(COUNTIF(B7:H7,"✅")/7,0) -> 0
A8: 🧮 DSA | B8: ☐ | C8: ☐ | D8: ☐ | E8: ☐ | F8: ☐ | G8: ☐ | H8: ☐ | I8: =IFERROR(COUNTIF(B8:H8,"✅")/7,0) -> 0
A9: 🤖 AI & Automation | B9: ☐ | C9: ☐ | D9: ☐ | E9: ☐ | F9: ☐ | G9: ☐ | H9: ☐ | I9: =IFERROR(COUNTIF(B9:H9,"✅")/7,0) -> 0
A10: 💻 Tech | B10: ☐ | C10: ☐ | D10: ☐ | E10: ☐ | F10: ☐ | G10: ☐ | H10: ☐ | I10: =IFERROR(COUNTIF(B10:H10,"✅")/7,0) -> 0
A11: 🎬 Creative | B11: ☐ | C11: ☐ | D11: ☐ | E11: ☐ | F11: ☐ | G11: ☐ | H11: ☐ | I11: =IFERROR(COUNTIF(B11:H11,"✅")/7,0) -> 0
B12: ☐ | C12: ☐ | D12: ☐ | E12: ☐ | F12: ☐ | G12: ☐ | H12: ☐ | I12: =IFERROR(COUNTIF(B12:H12,"✅")/7,0) -> 0
B13: ☐ | C13: ☐ | D13: ☐ | E13: ☐ | F13: ☐ | G13: ☐ | H13: ☐ | I13: =IFERROR(COUNTIF(B13:H13,"✅")/7,0) -> 0
B14: ☐ | C14: ☐ | D14: ☐ | E14: ☐ | F14: ☐ | G14: ☐ | H14: ☐ | I14: =IFERROR(COUNTIF(B14:H14,"✅")/7,0) -> 0
B15: ☐ | C15: ☐ | D15: ☐ | E15: ☐ | F15: ☐ | G15: ☐ | H15: ☐ | I15: =IFERROR(COUNTIF(B15:H15,"✅")/7,0) -> 0

Sheet COO_Operations
A1: ←
A3: TASK | B3: MON | C3: TUE | D3: WED | E3: THU | F3: FRI | G3: SAT | H3: SUN | I3: %
A4: 📋 Office Tasks | B4: ☐ | C4: ☐ | D4: ☐ | E4: ☐ | F4: ☐ | G4: ☐ | H4: ☐ | I4: =IFERROR(COUNTIF(B4:H4,"✅")/7,0) -> 0
A5: 📊 Reports | B5: ☐ | C5: ☐ | D5: ☐ | E5: ☐ | F5: ☐ | G5: ☐ | H5: ☐ | I5: =IFERROR(COUNTIF(B5:H5,"✅")/7,0) -> 0
A6: 📁 File Mgmt | B6: ☐ | C6: ☐ | D6: ☐ | E6: ☐ | F6: ☐ | G6: ☐ | H6: ☐ | I6: =IFERROR(COUNTIF(B6:H6,"✅")/7,0) -> 0
A7: 📧 Emails | B7: ☐ | C7: ☐ | D7: ☐ | E7: ☐ | F7: ☐ | G7: ☐ | H7: ☐ | I7: =IFERROR(COUNTIF(B7:H7,"✅")/7,0) -> 0
A8: 📞 Meetings | B8: ☐ | C8: ☐ | D8: ☐ | E8: ☐ | F8: ☐ | G8: ☐ | H8: ☐ | I8: =IFERROR(COUNTIF(B8:H8,"✅")/7,0) -> 0
A9: 🎬 YouTube | B9: ☐ | C9: ☐ | D9: ☐ | E9: ☐ | F9: ☐ | G9: ☐ | H9: ☐ | I9: =IFERROR(COUNTIF(B9:H9,"✅")/7,0) -> 0
A10: 🛒 Grocery | B10: ☐ | C10: ☐ | D10: ☐ | E10: ☐ | F10: ☐ | G10: ☐ | H10: ☐ | I10: =IFERROR(COUNTIF(B10:H10,"✅")/7,0) -> 0
B11: ☐ | C11: ☐ | D11: ☐ | E11: ☐ | F11: ☐ | G11: ☐ | H11: ☐ | I11: =IFERROR(COUNTIF(B11:H11,"✅")/7,0) -> 0
B12: ☐ | C12: ☐ | D12: ☐ | E12: ☐ | F12: ☐ | G12: ☐ | H12: ☐ | I12: =IFERROR(COUNTIF(B12:H12,"✅")/7,0) -> 0
B13: ☐ | C13: ☐ | D13: ☐ | E13: ☐ | F13: ☐ | G13: ☐ | H13: ☐ | I13: =IFERROR(COUNTIF(B13:H13,"✅")/7,0) -> 0
B14: ☐ | C14: ☐ | D14: ☐ | E14: ☐ | F14: ☐ | G14: ☐ | H14: ☐ | I14: =IFERROR(COUNTIF(B14:H14,"✅")/7,0) -> 0
B15: ☐ | C15: ☐ | D15: ☐ | E15: ☐ | F15: ☐ | G15: ☐ | H15: ☐ | I15: =IFERROR(COUNTIF(B15:H15,"✅")/7,0) -> 0

Sheet CPO_Voice
A1: ←
A3: PRACTICE | B3: MON | C3: TUE | D3: WED | E3: THU | F3: FRI | G3: SAT | H3: SUN | I3: %
A4: 🎤 Voice Warm-up | B4: ☐ | C4: ☐ | D4: ☐ | E4: ☐ | F4: ☐ | G4: ☐ | H4: ☐ | I4: =IFERROR(COUNTIF(B4:H4,"✅")/7,0) -> 0
A5: 🗣️ Mirror Talk | B5: ☐ | C5: ☐ | D5: ☐ | E5: ☐ | F5: ☐ | G5: ☐ | H5: ☐ | I5: =IFERROR(COUNTIF(B5:H5,"✅")/7,0) -> 0
A6: 📹 Record Speech | B6: ☐ | C6: ☐ | D6: ☐ | E6: ☐ | F6: ☐ | G6: ☐ | H6: ☐ | I6: =IFERROR(COUNTIF(B6:H6,"✅")/7,0) -> 0
A7: 📚 Read Aloud | B7: ☐ | C7: ☐ | D7: ☐ | E7: ☐ | F7: ☐ | G7: ☐ | H7: ☐ | I7: =IFERROR(COUNTIF(B7:H7,"✅")/7,0) -> 0
A8: 💬 Talk to Stranger | B8: ☐ | C8: ☐ | D8: ☐ | E8: ☐ | F8: ☐ | G8: ☐ | H8: ☐ | I8: =IFERROR(COUNTIF(B8:H8,"✅")/7,0) -> 0
A9: 💪 Fear Challenge | B9: ☐ | C9: ☐ | D9: ☐ | E9: ☐ | F9: ☐ | G9: ☐ | H9: ☐ | I9: =IFERROR(COUNTIF(B9:H9,"✅")/7,0) -> 0
B10: ☐ | C10: ☐ | D10: ☐ | E10: ☐ | F10: ☐ | G10: ☐ | H10: ☐ | I10: =IFERROR(COUNTIF(B10:H10,"✅")/7,0) -> 0
B11: ☐ | C11: ☐ | D11: ☐ | E11: ☐ | F11: ☐ | G11: ☐ | H11: ☐ | I11: =IFERROR(COUNTIF(B11:H11,"✅")/7,0) -> 0
B12: ☐ | C12: ☐ | D12: ☐ | E12: ☐ | F12: ☐ | G12: ☐ | H12: ☐ | I12: =IFERROR(COUNTIF(B12:H12,"✅")/7,0) -> 0
B13: ☐ | C13: ☐ | D13: ☐ | E13: ☐ | F13: ☐ | G13: ☐ | H13: ☐ | I13: =IFERROR(COUNTIF(B13:H13,"✅")/7,0) -> 0
B14: ☐ | C14: ☐ | D14: ☐ | E14: ☐ | F14: ☐ | G14: ☐ | H14: ☐ | I14: =IFERROR(COUNTIF(B14:H14,"✅")/7,0) -> 0
B15: ☐ | C15: ☐ | D15: ☐ | E15: ☐ | F15: ☐ | G15: ☐ | H15: ☐ | I15: =IFERROR(COUNTIF(B15:H15,"✅")/7,0) -> 0

Sheet Weekly_Meal_Plan
A1: ←
A3: MEAL | B3: MON 6 | C3: TUE 7 | D3: WED 8 | E3: THU 9 | F3: FRI 10 | G3: SAT 11 | H3: SUN 5
A4: 🍳 Breakfast (7:30 AM) | B4: Oats + Milk | C4: Poha | D4: Upma | E4: Paratha | F4: Idli + Sambar | G4: Dosa | H4: Puri + Sabzi
A5: 🍎 Mid-Morning (10:30) | B5: Fruit Bowl | C5: Banana + Nuts | D5: Apple | E5: Orange | F5: Papaya | G5: Watermelon | H5: Guava
A6: 🍱 Lunch (1:00 PM) | B6: Dal + Rice | C6: Roti + Sabzi | D6: Rajma + Rice | E6: Chole + Roti | F6: Kadhi + Rice | G6: Biryani | H6: Pulao
A7: 🥗 Evening Snack (4:30) | B7: Sprouts | C7: Samosa | D7: Sandwich | E7: Pakoda | F7: Bhel Puri | G7: Dhokla | H7: Vada
A8: 🍽️ Dinner (8:00 PM) | B8: Roti + Paneer | C8: Khichdi | D8: Roti + Dal | E8: Fried Rice | F8: Noodles | G8: Pizza | H8: Pasta
A9: 🥛 Bedtime (9:30 PM) | B9: Warm Milk | C9: Turmeric Milk | D9: Warm Milk | E9: Warm Milk | F9: Turmeric Milk | G9: Warm Milk | H9: Warm Milk

Sheet Grocery_List
A1: ←
A3: ✓ | B3: ITEM | C3: CATEGORY | D3: QTY | E3: PRICE | F3: TOTAL
A4: ☐ | B4: Rice | C4: Grains | D4: 5 kg | E4: 80 | F4: 400
A5: ☐ | B5: Wheat Flour | C5: Grains | D5: 5 kg | E5: 45 | F5: 225
A6: ☐ | B6: Dal (Toor) | C6: Pulses | D6: 2 kg | E6: 120 | F6: 240
A7: ☐ | B7: Dal (Moong) | C7: Pulses | D7: 1 kg | E7: 110 | F7: 110
A8: ☐ | B8: Rajma | C8: Pulses | D8: 1 kg | E8: 130 | F8: 130
A9: ☐ | B9: Chole | C9: Pulses | D9: 1 kg | E9: 100 | F9: 100
A10: ☐ | B10: Milk | C10: Dairy | D10: 5 L | E10: 60 | F10: 300
A11: ☐ | B11: Curd | C11: Dairy | D11: 2 kg | E11: 80 | F11: 160
A12: ☐ | B12: Paneer | C12: Dairy | D12: 500 g | E12: 350 | F12: 350
A13: ☐ | B13: Ghee | C13: Dairy | D13: 500 g | E13: 550 | F13: 550
A14: ☐ | B14: Tomato | C14: Vegetables | D14: 2 kg | E14: 40 | F14: 80
A15: ☐ | B15: Onion | C15: Vegetables | D15: 3 kg | E15: 30 | F15: 90
... A29: ☐ | B29: Coffee | C29: Beverages | D29: 200 g | E29: 400 | F29: 400
B30: TOTAL | F30: =SUM(F4:F29) -> 4185

Sheet Water_Health
A1: ←
A3: 💧 WATER INTAKE (Target: 8 glasses/day)
A4: TIME | B4: MON | C4: TUE | D4: WED | E4: THU | F4: FRI | G4: SAT | H4: SUN | I4: TOTAL
A5: 0.25 | B5: ☐ | C5: ☐ | D5: ☐ | E5: ☐ | F5: ☐ | G5: ☐ | H5: ☐ | I5: =COUNTIF(B5:H5,"✅") -> 0
A6: 0.33333333 | B6: ☐ | C6: ☐ | D6: ☐ | E6: ☐ | F6: ☐ | G6: ☐ | H6: ☐ | I6: =COUNTIF(B6:H6,"✅") -> 0
A7: 0.41666667 | B7: ☐ | C7: ☐ | D7: ☐ | E7: ☐ | F7: ☐ | G7: ☐ | H7: ☐ | I7: =COUNTIF(B7:H7,"✅") -> 0
A8: 0.5 | B8: ☐ | C8: ☐ | D8: ☐ | E8: ☐ | F8: ☐ | G8: ☐ | H8: ☐ | I8: =COUNTIF(B8:H8,"✅") -> 0
A9: 0.58333333 | B9: ☐ | C9: ☐ | D9: ☐ | E9: ☐ | F9: ☐ | G9: ☐ | H9: ☐ | I9: =COUNTIF(B9:H9,"✅") -> 0
A10: 0.66666667 | B10: ☐ | C10: ☐ | D10: ☐ | E10: ☐ | F10: ☐ | G10: ☐ | H10: ☐ | I10: =COUNTIF(B10:H10,"✅") -> 0
A11: 0.75 | B11: ☐ | C11: ☐ | D11: ☐ | E11: ☐ | F11: ☐ | G11: ☐ | H11: ☐ | I11: =COUNTIF(B11:H11,"✅") -> 0
A12: 0.83333333 | B12: ☐ | C12: ☐ | D12: ☐ | E12: ☐ | F12: ☐ | G12: ☐ | H12: ☐ | I12: =COUNTIF(B12:H12,"✅") -> 0

Sheet Calorie_Tracker
A1: ←
A3: MEAL | B3: MON | C3: TUE | D3: WED | E3: THU | F3: FRI | G3: SAT | H3: SUN
A4: 🍳 Breakfast | B4: 350 | C4: 320 | D4: 400 | E4: 380 | F4: 420 | G4: 450 | H4: 380
A5: 🍎 Mid-Morning | B5: 150 | C5: 180 | D5: 120 | E5: 160 | F5: 140 | G5: 200 | H5: 150
A6: 🍱 Lunch | B6: 600 | C6: 550 | D6: 650 | E6: 580 | F6: 620 | G6: 700 | H6: 600
A7: 🥗 Evening Snack | B7: 200 | C7: 250 | D7: 180 | E7: 220 | F7: 240 | G7: 280 | H7: 200
A8: 🍽️ Dinner | B8: 500 | C8: 480 | D8: 550 | E8: 520 | F8: 540 | G8: 600 | H8: 500
A9: 🥛 Bedtime | B9: 150 | C9: 150 | D9: 150 | E9: 150 | F9: 150 | G9: 150 | H9: 150
A10: 📊 DAILY TOTAL | B10: =SUM(B4:B9) -> 1950 | C10: =SUM(C4:C9) -> 1930 | D10: =SUM(D4:D9) -> 2050 | E10: =SUM(E4:E9) -> 2010 | F10: =SUM(F4:F9) -> 2110 | G10: =SUM(G4:G9) -> 2380 | H10: =SUM(H4:H9) -> 1980

Sheet Meal_Prep
A1: ←
A3: DAY | B3: PREP TIME | C3: TASK | D3: DISH | E3: STATUS | F3: NOTES
A4: Sunday | B4: 0.41666667 | C4: Soak Dal & Rice | D4: Monday Lunch | E4: ☐ | F4: Soak overnight
A5: Sunday | B5: 0.70833333 | C5: Chop Vegetables | D5: Mon-Wed | E5: ☐ | F5: Store in fridge
A6: Monday | B6: 0.29166667 | C6: Boil Eggs | D6: Mon-Wed | E6: ☐ | F6: 6 eggs
A7: Monday | B7: 0.83333333 | C7: Prepare Masala | D7: Tue-Fri | E7: ☐ | F7: Ginger-garlic paste
A8: Tuesday | B8: 0.875 | C8: Make Curd | D8: Wed-Sun | E8: ☐ | F8: From 1L milk
A9: Wednesday | B9: 0.83333333 | C9: Knead Dough | D9: Thursday Roti | E9: ☐ | F9: Store in fridge
A10: Thursday | B10: 0.83333333 | C10: Cut Fruits | D10: Fri-Sat | E10: ☐ | F10: Store in box
A11: Friday | B11: 0.83333333 | C11: Prep Paneer | D11: Saturday | E11: ☐ | F11: Marinate
A12: Saturday | B12: 0.41666667 | C12: Grocery Shopping | D12: Next Week | E12: ☐ | F12: As per list
A13: Saturday | B13: 0.70833333 | C13: Clean Kitchen | D13: Weekly | E13: ☐ | F13: Deep clean

Sheet Recipe_Collection
A1: ←
A3: # | B3: RECIPE NAME | C3: TYPE | D3: TIME | E3: STATUS
A4: 1 | B4: 🥣 Oats with Milk & Nuts | C4: Breakfast | D4: 10 min | E4: ✅
A5: 2 | B5: 🍚 Poha with Peanuts | C5: Breakfast | D5: 15 min | E5: ✅
A6: 3 | B6: 🥘 Upma with Veggies | C6: Breakfast | D6: 20 min | E6: ✅
A7: 4 | B7: 🫓 Aloo Paratha | C7: Breakfast | D7: 30 min | E7: ✅
A8: 5 | B8: 🍚 Dal Tadka + Rice | C8: Lunch | D8: 30 min | E8: ✅
A9: 6 | B9: 🫘 Rajma Chawal | C9: Lunch | D9: 45 min | E9: ✅
A10: 7 | B10: 🥘 Chole Bhature | C10: Lunch | D10: 40 min | E10: ✅
A11: 8 | B11: 🍚 Veg Biryani | C11: Lunch | D11: 50 min | E11: ✅
A12: 9 | B12: 🧀 Paneer Butter Masala | C12: Dinner | D12: 40 min | E12: ✅
A13: 10 | B13: 🍲 Vegetable Khichdi | C13: Dinner | D13: 25 min | E13: ✅
A14: 11 | B14: 🍜 Hakka Noodles | C14: Dinner | D14: 30 min | E14: ✅
A15: 12 | B15: 🍕 Homemade Pizza | C15: Dinner | D15: 45 min | E15: ⏳
... A21: 18 | B21: 🍮 Gulab Jamun | C21: Dessert | D21: 45 min | E21: ⏳

Sheet WeightGain_MealPlan
A1: ←
A3: MEAL | B3: TIME | C3: MON | D3: TUE | E3: WED | F3: THU | G3: FRI | H3: SAT | I3: SUN | J3: CAL
A4: 🌅 Pre-Workout | B4: 0.25 | C4: Banana + PB | D4: Banana Shake | E4: Oats + Honey | F4: Banana + Dates | G4: Banana Shake | H4: Fruit Salad | I4: Mango Shake | J4: 350
A5: 🍳 Breakfast | B5: 0.3125 | C5: 4 Eggs + Paratha | D5: Poha + Curd | E5: Upma + Eggs | F5: 4 Eggs + Toast | G5: Idli + Sambar | H5: Dosa + Egg | I5: Puri + Sabzi | J5: 650
A6: 🍎 Mid-Morning | B6: 0.4375 | C6: Dry Fruits + Milk | D6: Peanut Chikki | E6: Banana Shake | F6: Almonds + Dates | G6: Fruit + Yogurt | H6: Mango Shake | I6: Banana + Honey | J6: 400
A7: 🍱 Lunch | B7: 0.54166667 | C7: Dal + Rice + Paneer | D7: Rajma + Rice | E7: Chicken Curry | F7: Chole + Rice | G7: Kadhi + Rice | H7: Biryani + Raita | I7: Pulao + Paneer | J7: 750
A8: 🥤 Post-Workout | B8: 0.70833333 | C8: Whey Protein | D8: Egg Shake | E8: PB Shake | F8: Whey + Banana | G8: Mass Gainer | H8: Protein Smoothie | I8: Milk + Dates | J8: 450
A9: 🍽️ Dinner | B9: 0.83333333 | C9: Roti + Paneer | D9: Khichdi + Ghee | E9: Roti + Chicken | F9: Fried Rice + Egg | G9: Noodles + Paneer | H9: Pizza + Milk | I9: Pasta + Cheese | J9: 600
A10: 🥛 Bedtime | B10: 0.91666667 | C10: Warm Milk + Ghee | D10: Turmeric Milk | E10: Warm Milk + Honey | F10: Milk + Almonds | G10: Warm Milk + Ghee | H10: Turmeric Milk | I10: Warm Milk | J10: 300
A11: 📊 DAILY TOTAL | J11: =SUM(J4:J10) -> 3500

Sheet Calorie_Protein
A1: ←
A3: MEAL | B3: CAL | C3: PROTEIN (g) | D3: CARBS (g) | E3: FAT (g) | F3: STATUS
A4: 🌅 Pre-Workout | B4: 350 | C4: 10 | D4: 60 | E4: 8 | F4: ☐
A5: 🍳 Breakfast | B5: 650 | C5: 25 | D5: 80 | E5: 20 | F5: ☐
A6: 🍎 Mid-Morning | B6: 400 | C6: 15 | D6: 45 | E6: 12 | F6: ☐
A7: 🍱 Lunch | B7: 750 | C7: 35 | D7: 95 | E7: 22 | F7: ☐
A8: 🥤 Post-Workout | B8: 450 | C8: 35 | D8: 50 | E8: 10 | F8: ☐
A9: 🍽️ Dinner | B9: 600 | C9: 30 | D9: 70 | E9: 20 | F9: ☐
A10: 🥛 Bedtime | B10: 300 | C10: 15 | D10: 30 | E10: 12 | F10: ☐
A11: 📊 TOTAL | B11: =SUM(B4:B10) -> 3500 | C11: =SUM(C4:C10) -> 165 | D11: =SUM(D4:D10) -> 430 | E11: =SUM(E4:E10) -> 104 | F11: ✅

Sheet Weight_Tracker
A1: ←
A3: WEEK | B3: DATE | C3: WEIGHT (kg) | D3: CHANGE (kg) | E3: CHEST (in) | F3: WAIST (in) | G3: NOTES
A4: Week 1 | C4: 0 | D4: - | E4: 0 | F4: 0
A5: Week 2 | C5: 0 | D5: =C5-C4 -> 0 | E5: 0 | F5: 0
A6: Week 3 | C6: 0 | D6: =C6-C5 -> 0 | E6: 0 | F6: 0
A7: Week 4 | C7: 0 | D7: =C7-C6 -> 0 | E7: 0 | F7: 0
A8: Week 5 | C8: 0 | D8: =C8-C7 -> 0 | E8: 0 | F8: 0
A9: Week 6 | C9: 0 | D9: =C9-C8 -> 0 | E9: 0 | F9: 0
A10: Week 7 | C10: 0 | D10: =C10-C9 -> 0 | E10: 0 | F10: 0
A11: Week 8 | C11: 0 | D11: =C11-C10 -> 0 | E11: 0 | F11: 0
A12: Week 9 | C12: 0 | D12: =C12-C11 -> 0 | E12: 0 | F12: 0
A13: Week 10 | C13: 0 | D13: =C13-C12 -> 0 | E13: 0 | F13: 0
A14: Week 11 | C14: 0 | D14: =C14-C13 -> 0 | E14: 0 | F14: 0
A15: Week 12 | C15: 0 | D15: =C15-C14 -> 0 | E15: 0 | F15: 0

Sheet Supplements
A1: ←
A3: SUPPLEMENT | B3: DOSE | C3: TIME | D3: PURPOSE | E3: MON | F3: TUE | G3: WED | H3: THU | I3: FRI | J3: SAT | K3: SUN
A4: 💪 Whey Protein | B4: 1 scoop | C4: Post-Workout | D4: Muscle recovery | E4: ☐ | F4: ☐ | G4: ☐ | H4: ☐ | I4: ☐ | J4: ☐ | K4: ☐
A5: 🍚 Mass Gainer | B5: 2 scoops | C5: Between meals | D5: Extra calories | E5: ☐ | F5: ☐ | G5: ☐ | H5: ☐ | I5: ☐ | J5: ☐ | K5: ☐
A6: 💊 Multivitamin | B6: 1 tablet | C6: After breakfast | D6: Overall health | E6: ☐ | F6: ☐ | G6: ☐ | H6: ☐ | I6: ☐ | J6: ☐ | K6: ☐
A7: 🐟 Omega-3 | B7: 1 capsule | C7: After dinner | D7: Joint + brain | E7: ☐ | F7: ☐ | G7: ☐ | H7: ☐ | I7: ☐ | J7: ☐ | K7: ☐
A8: ⚡ Creatine | B8: 5g | C8: Pre-workout | D8: Strength + power | E8: ☐ | F8: ☐ | G8: ☐ | H8: ☐ | I8: ☐ | J8: ☐ | K8: ☐
A9: 🌿 BCAA | B9: 1 scoop | C9: Intra-workout | D9: Muscle preservation | E9: ☐ | F9: ☐ | G9: ☐ | H9: ☐ | I9: ☐ | J9: ☐ | K9: ☐
A10: ☀️ Vitamin D3 | B10: 1 tablet | C10: After breakfast | D10: Bone health | E10: ☐ | F10: ☐ | G10: ☐ | H10: ☐ | I10: ☐ | J10: ☐ | K10: ☐
A11: 🦴 Calcium | B11: 1 tablet | C11: After dinner | D11: Bone strength | E11: ☐ | F11: ☐ | G11: ☐ | H11: ☐ | I11: ☐ | J11: ☐ | K11: ☐

Sheet Workout_Diet
A1: ←
A3: DAY | B3: WORKOUT | C3: TIME | D3: PRE-MEAL | E3: POST-MEAL | F3: FOCUS
A4: Monday | B4: Chest + Triceps | C4: 6:00-7:30 AM | D4: Banana + PB | E4: Whey + Milk | F4: Push
A5: Tuesday | B5: Back + Biceps | C5: 6:00-7:30 AM | D5: Banana + Dates | E5: Egg Shake | F5: Pull
A6: Wednesday | B6: Legs + Abs | C6: 6:00-7:30 AM | D6: Oats + Honey | E6: Mass Gainer | F6: Lower
A7: Thursday | B7: Shoulders + Arms | C7: 6:00-7:30 AM | D7: Banana + PB | E7: Whey + Milk | F7: Push
A8: Friday | B8: Chest + Back | C8: 6:00-7:30 AM | D8: Dates + Milk | E8: Protein Smoothie | F8: Full
A9: Saturday | B9: Full Body + Cardio | C9: 7:00-8:30 AM | D9: Banana Shake | E9: Whey + Banana | F9: Full
A10: Sunday | B10: REST + Recovery | C10: — | D10: Normal | E10: Normal | F10: Rest

Sheet CEO_Dashboard
A1: ←
A3: 📊 CEO PERFORMANCE METRICS
A4: Skills Mastered | C4: Skills Practicing | E4: Strategy % | G4: Leadership % | I4: Communication % | K4: Decisions % | M4: Personal % | O4: Overall
A5: =COUNTIF(Skills_Tracker!G3:G75,"Done") -> 0 | C5: =COUNTIF(Skills_Tracker!G3:G75,"In Progress") -> 0 | E5: =IFERROR(AVERAGE(Skills_Tracker!F3:F10),0) -> 0 | G5: =IFERROR(AVERAGE(Skills_Tracker!F11:F20),0) -> 0 | I5: =IFERROR(AVERAGE(Skills_Tracker!F21:F28),0) -> 0 | K5: =IFERROR(AVERAGE(Skills_Tracker!F34:F39),0) -> 0 | M5: =IFERROR(AVERAGE(Skills_Tracker!F56:F63),0) -> 0 | O5: =IF(E5>=0.9,"S+",IF(E5>=0.8,"A+",IF(E5>=0.7,"A","B"))) -> B

Sheet Skills_Tracker
A1: 👑 CEO SKILLS TRACKER — 73 SKILLS
A2: S.No | B2: Category | C2: Skill | D2: Priority | E2: Target | F2: Current | G2: Status | H2: Notes
A3: 1 | B3: 🧠 Strategic Thinking | C3: 1.1 Vision Setting | D3: 🔴 High | E3: 10 | F3: 0 | G3: =IF(F3>=9,"Done",IF(F3>0,"In Progress","Not Started")) -> Not Started
A4: 2 | B4: 🧠 Strategic Thinking | C4: 1.2 Long-Term Planning | D4: 🔴 High | E4: 10 | F4: 0 | G4: =IF(F4>=9,"Done",IF(F4>0,"In Progress","Not Started")) -> Not Started
A5: 3 | B5: 🧠 Strategic Thinking | C5: 1.3 Market Awareness | D5: 🟡 Medium | E5: 10 | F5: 0 | G5: =IF(F5>=9,"Done",IF(F5>0,"In Progress","Not Started")) -> Not Started
A6: 4 | B6: 🧠 Strategic Thinking | C6: 1.4 Pattern Recognition | D6: 🟡 Medium | E6: 10 | F6: 0 | G6: =IF(F6>=9,"Done",IF(F6>0,"In Progress","Not Started")) -> Not Started
A7: 5 | B7: 🧠 Strategic Thinking | C7: 1.5 Systems Thinking | D7: 🔴 High | E7: 10 | F7: 0 | G7: =IF(F7>=9,"Done",IF(F7>0,"In Progress","Not Started")) -> Not Started
A8: 6 | B8: 🧠 Strategic Thinking | C8: 1.6 Scenario Planning | D8: 🟡 Medium | E8: 10 | F8: 0 | G8: =IF(F8>=9,"Done",IF(F8>0,"In Progress","Not Started")) -> Not Started
A9: 7 | B9: 🧠 Strategic Thinking | C9: 1.7 Resource Allocation | D9: 🔴 High | E9: 10 | F9: 0 | G9: =IF(F9>=9,"Done",IF(F9>0,"In Progress","Not Started")) -> Not Started
A10: 8 | B10: 🧠 Strategic Thinking | C10: 1.8 Competitive Analysis | D10: 🟡 Medium | E10: 10 | F10: 0 | G10: =IF(F10>=9,"Done",IF(F10>0,"In Progress","Not Started")) -> Not Started
A11: 9 | B11: 👥 Leadership | C11: 2.1 Vision Communication | D11: 🔴 High | E11: 10 | F11: 0 | G11: =IF(F11>=9,"Done",IF(F11>0,"In Progress","Not Started")) -> Not Started
A12: 10 | B12: 👥 Leadership | C12: 2.2 Delegation | D12: 🔴 High | E12: 10 | F12: 0 | G12: =IF(F12>=9,"Done",IF(F12>0,"In Progress","Not Started")) -> Not Started
A13: 11 | B13: 👥 Leadership | C13: 2.3 Motivation | D13: 🔴 High | E13: 10 | F13: 0 | G13: =IF(F13>=9,"Done",IF(F13>0,"In Progress","Not Started")) -> Not Started
A14: 12 | B14: 👥 Leadership | C14: 2.4 Coaching | D14: 🔴 High | E14: 10 | F14: 0 | G14: =IF(F14>=9,"Done",IF(F14>0,"In Progress","Not Started")) -> Not Started
... A75: 73 | B75: 🔧 Technical | C75: 10.5 Process Optimization | D75: 🟡 Medium | E75: 10 | F75: 0 | G75: =IF(F75>=9,"Done",IF(F75>0,"In Progress","Not Started")) -> Not Started

Sheet CEO_Daily_Schedule
A1: ⏰ CEO DAILY SCHEDULE — 5 AM to 10 PM
A2: TIME | B2: ACTIVITY | C2: SKILL FOCUS | D2: DURATION | E2: CATEGORY | F2: DONE
A3: 5:00 - 6:00 | B3: 🏋️ Exercise + Meditation | C3: Health + Discipline | D3: 1 hr | E3: Personal
A4: 6:00 - 7:00 | B4: 📚 Reading (Books + News) | C4: Learning + Strategy | D4: 1 hr | E4: Knowledge
A5: 7:00 - 8:00 | B5: 🧠 Deep Work (Strategic) | C5: Focus + Strategy | D5: 1 hr | E5: Execution
A6: 8:00 - 9:00 | B6: 📧 Emails + Communication | C6: Writing | D6: 1 hr | E6: Communication
A7: 9:00 - 10:00 | B7: 👥 Team Meeting | C7: Leadership | D7: 1 hr | E7: Leadership
A8: 10:00 - 12:00 | B8: 🚀 Critical Work | C8: Execution | D8: 2 hr | E8: Execution
A9: 12:00 - 1:00 | B9: 🍽️ Lunch + Networking | C9: Networking | D9: 1 hr | E9: External
A10: 1:00 - 3:00 | B10: 🎯 Meetings + Decisions | C10: Decision Making | D10: 2 hr | E10: Decisions
A11: 3:00 - 5:00 | B11: 🧠 Deep Work | C11: Focus | D11: 2 hr | E11: Execution
A12: 5:00 - 6:00 | B12: 🤝 1-on-1s | C12: People Management | D12: 1 hr | E12: People
A13: 6:00 - 7:00 | B13: 💰 Financial Review | C13: Finance | D13: 1 hr | E13: Finance
A14: 7:00 - 8:00 | B14: 🍽️ Dinner + Family | C14: Life Balance | D14: 1 hr | E14: Personal
... A16: 9:00 - 10:00 | B16: 📝 Journal + Review | C16: Self-Awareness | D16: 1 hr | E16: Personal
A17: 0.41666667 | B17: 🛏️ Sleep | C17: Health | D17: — | E17: Personal

Sheet 52-Week_Plan
A1: 📅 52-WEEK CEO DEVELOPMENT PLAN
A2: Weeks | B2: Focus Area | C2: Goal | D2: Daily Action | E2: Progress | F2: Status
A3: W1-4 | B3: 🧠 Strategic Thinking | C3: Master vision + planning | D3: 30 min strategy reading | E3: 0 | F3: =IF(E3>=0.9,"🟢 Done",IF(E3>=0.5,"🟡 Progress",IF(E3>0,"🔴 Started","⚪ Not Started"))) -> ⚪ Not Started
A4: W5-8 | B4: 👥 Leadership | C4: Lead self + others | D4: 1 leadership action | E4: 0 | F4: =IF(E4>=0.9,"🟢 Done",IF(E4>=0.5,"🟡 Progress",IF(E4>0,"🔴 Started","⚪ Not Started"))) -> ⚪ Not Started
A5: W9-12 | B5: 💬 Communication | C5: Public speaking | D5: 10 min mirror + record | E5: 0 | F5: =IF(E5>=0.9,"🟢 Done",IF(E5>=0.5,"🟡 Progress",IF(E5>0,"🔴 Started","⚪ Not Started"))) -> ⚪ Not Started
A6: W13-16 | B6: 💰 Financial Literacy | C6: Master finance | D6: 30 min finance study | E6: 0 | F6: =IF(E6>=0.9,"🟢 Done",IF(E6>=0.5,"🟡 Progress",IF(E6>0,"🔴 Started","⚪ Not Started"))) -> ⚪ Not Started
A7: W17-20 | B7: 🎯 Decision Making | C7: Fast decisions | D7: 1 decision analysis | E7: 0 | F7: =IF(E7>=0.9,"🟢 Done",IF(E7>=0.5,"🟡 Progress",IF(E7>0,"🔴 Started","⚪ Not Started"))) -> ⚪ Not Started
A8: W21-24 | B8: 🤝 People Management | C8: Network + team | D8: 3 connections/week | E8: 0 | F8: =IF(E8>=0.9,"🟢 Done",IF(E8>=0.5,"🟡 Progress",IF(E8>0,"🔴 Started","⚪ Not Started"))) -> ⚪ Not Started
A9: W25-28 | B9: 🚀 Execution | C9: Deep work mastery | D9: 4 hr deep work | E9: 0 | F9: =IF(E9>=0.9,"🟢 Done",IF(E9>=0.5,"🟡 Progress",IF(E9>0,"🔴 Started","⚪ Not Started"))) -> ⚪ Not Started
A10: W29-32 | B10: 🧘 Personal Mastery | C10: Emotional control | D10: Meditation + journal | E10: 0 | F10: =IF(E10>=0.9,"🟢 Done",IF(E10>=0.5,"🟡 Progress",IF(E10>0,"🔴 Started","⚪ Not Started"))) -> ⚪ Not Started
A11: W33-36 | B11: 🌐 External Relations | C11: Industry presence | D11: Content + networking | E11: 0 | F11: =IF(E11>=0.9,"🟢 Done",IF(E11>=0.5,"🟡 Progress",IF(E11>0,"🔴 Started","⚪ Not Started"))) -> ⚪ Not Started
A12: W37-40 | B12: 🔧 Technical | C12: Data analytics | D12: 1 hr technical study | E12: 0 | F12: =IF(E12>=0.9,"🟢 Done",IF(E12>=0.5,"🟡 Progress",IF(E12>0,"🔴 Started","⚪ Not Started"))) -> ⚪ Not Started
A13: W41-44 | B13: 🏆 Integration | C13: All skills combined | D13: Weekly CEO review | E13: 0 | F13: =IF(E13>=0.9,"🟢 Done",IF(E13>=0.5,"🟡 Progress",IF(E13>0,"🔴 Started","⚪ Not Started"))) -> ⚪ Not Started
A14: W45-48 | B14: 🚀 Mastery | C14: Execute like CEO | D14: Daily CEO routine | E14: 0 | F14: =IF(E14>=0.9,"🟢 Done",IF(E14>=0.5,"🟡 Progress",IF(E14>0,"🔴 Started","⚪ Not Started"))) -> ⚪ Not Started
A15: W49-52 | B15: 📊 Review + 2027 Plan | C15: Year in review | D15: Complete yearly review | E15: 0 | F15: =IF(E15>=0.9,"🟢 Done",IF(E15>=0.5,"🟡 Progress",IF(E15>0,"🔴 Started","⚪ Not Started"))) -> ⚪ Not Started

Sheet CEO_Books
A1: 📚 CEO BOOK RECOMMENDATIONS — 25 BOOKS
A2: S.No | B2: Book Title | C2: Author | D2: Skill Focus | E2: Priority | F2: Read?
A3: 1 | B3: The 5 Second Rule | C3: Mel Robbins | D3: Fear + Action | E3: 🔴 High | F3: ☐
A4: 2 | B4: Feel the Fear and Do It Anyway | C4: Susan Jeffers | D4: Fear Management | E4: 🔴 High | F4: ☐
A5: 3 | B5: The Charisma Myth | C5: Olivia Fox Cabane | D5: Voice + Presence | E5: 🔴 High | F5: ☐
A6: 4 | B6: Talk Like TED | C6: Carmine Gallo | D6: Public Speaking | E6: 🔴 High | F6: ☐
A7: 5 | B7: The Art of Public Speaking | C7: Dale Carnegie | D7: Speaking | E7: 🔴 High | F7: ☐
A8: 6 | B8: The Gifts of Imperfection | C8: Brené Brown | D8: Insecurity | E8: 🔴 High | F8: ☐
A9: 7 | B9: Daring Greatly | C9: Brené Brown | D9: Vulnerability | E9: 🔴 High | F9: ☐
A10: 8 | B10: Atomic Habits | C10: James Clear | D10: Habit Building | E10: 🔴 High | F10: ☐
A11: 9 | B11: Deep Work | C11: Cal Newport | D11: Focus | E11: 🔴 High | F11: ☐
A12: 10 | B12: The 7 Habits of Highly Effective People | C12: Stephen Covey | D12: Leadership | E12: 🔴 High | F12: ☐
A13: 11 | B13: Zero to One | C13: Peter Thiel | D13: Strategy | E13: 🔴 High | F13: ☐
A14: 12 | B14: The Lean Startup | C14: Eric Ries | D14: Execution | E14: 🔴 High | F14: ☐
... A27: 25 | B27: Sapiens | C27: Yuval Noah Harari | D27: Big Picture | E27: 🟡 Medium | F27: ☐

Sheet CEO_Journal
A1: 📝 DAILY CEO JOURNAL
A3: 🎯 What was my #1 priority today?
A4: ✅ What did I complete?
A5: ❌ What did I miss?
A6: 📚 What did I learn?
A7: 🤝 Who did I help/connect with?
A8: 💰 How did I manage finances?
A9: 💪 How was my health?
A10: 🧠 What decision did I make?
A11: 🌟 What's my biggest win today?
A12: 🎯 What's my #1 priority tomorrow?

Sheet CEO_Mindset
A1: 👑 CEO MINDSET — DAILY AFFIRMATIONS
A3: 👑 I am the CEO of my life | B3: ☐
A4: 🎯 I make decisions with confidence | B4: ☐
A5: 💪 I embrace challenges as opportunities | B5: ☐
A6: 🧠 I learn from every failure | B6: ☐
A7: ❤️ I lead with empathy and strength | B7: ☐
A8: 🚀 I execute with discipline | B8: ☐
A9: 💰 I create and manage wealth wisely | B9: ☐
A10: 🌐 I build meaningful relationships | B10: ☐
A11: 🧘 I stay calm under pressure | B11: ☐
A12: 📚 I learn something new every day | B12: ☐
A13: 🙏 I am grateful for this journey | B13: ☐
A14: 🌟 I am becoming the best version of myself | B14: ☐
... A17: 🤝 I keep my commitments | B17: ☐

Sheet Daily_Diary
A1: 📔 DAILY DIARY
A2: ←
G3: Date: ______________________
B5: My Daily Journal

Sheet Weekly_Diary
A1: 📅 WEEKLY DIARY
A2: ←
B5: Monday
B7: Tuesday
B9: Wednesday
B11: Thursday
B13: Friday
B15: Saturday
B17: Sunday

Sheet Notes
A1: 📝 NOTES
A2: ←

Sheet Gratitude_Journal
A1: 🙏 GRATITUDE JOURNAL
A2: ←
B5: 1. Today I am grateful for...
B9: 2. A person who made me smile...
B13: 3. Something beautiful I noticed...
B17: 4. A lesson I learned...
B21: 5. Something I'm proud of...

Sheet Financial_Dashboard
A1: 💰 FINANCIAL DASHBOARD
A3: 📅 MONTH OVERVIEW
A4: 💵 Total Income | B4: 50000
A5: 💳 Total Expenses | B5: 29000
A6: 💰 Net Savings | B6: 21000
A7: 📊 Savings Rate (%) | B7: 42
A8: 🏦 Loan EMI | B8: 5000
A9: 💎 Investment | B9: 8000

Sheet Income_Tracker
A1: 💵 INCOME TRACKER
A3: DATE | B3: SOURCE | C3: CATEGORY | D3: AMOUNT | E3: STATUS | F3: MODE | G3: NOTES
A4: 46296 | B4: Salary | C4: 💼 Job | D4: 25000 | E4: ✅ | F4: Bank | G4: Oct salary
A5: 46300 | B5: Freelance | C5: 💻 Work | D5: 8000 | E5: ✅ | F5: UPI | G5: Web project
A6: 46305 | B6: Tutoring | C6: 📚 Teaching | D6: 3000 | E6: ✅ | F6: Cash | G6: Maths
A7: 46310 | B7: YouTube | C7: 📺 Content | D7: 2000 | E7: ⏳ | F7: Bank | G7: Ad revenue
A8: 46315 | B8: Side Hustle | C8: 🛍️ Reselling | D8: 5000 | E8: ⏳ | F8: UPI | G8: Online
A9: 46320 | B9: Investment | C9: 📈 Returns | D9: 2000 | E9: ⏳ | F9: Bank | G9: Mutual fund
A10: 46323 | B10: Bonus | C10: 🎁 Extra | D10: 3000 | E10: ⏳ | F10: Bank | G10: Performance
A11: 46325 | B11: Cashback | C11: 💳 Rewards | D11: 500 | E11: ⏳ | F11: UPI | G11: Credit card
A12: TOTAL | D12: =SUM(D4:D11) -> 48500

Sheet Expense_Tracker
A1: 💳 EXPENSE TRACKER
A3: DATE | B3: ITEM | C3: CATEGORY | D3: AMOUNT | E3: PAYMENT | F3: STATUS | G3: NOTES
A4: 46296 | B4: House Rent | C4: 🏠 Rent | D4: 10000 | E4: Bank | F4: ✅ | G4: Monthly
A5: 46297 | B5: Groceries | C5: 🍽️ Food | D5: 3000 | E5: Cash | F5: ✅ | G5: Weekly
A6: 46300 | B6: Petrol | C6: 🚗 Transport | D6: 1500 | E6: UPI | F6: ✅ | G6: Fuel
A7: 46302 | B7: Course Fee | C7: 📚 Education | D7: 5000 | E7: Bank | F7: ✅ | G7: Online
A8: 46305 | B8: Netflix+Spotify | C8: 📱 Subs | D8: 500 | E8: UPI | F8: ✅ | G8: Monthly
A9: 46307 | B9: Electricity | C9: 💡 Utilities | D9: 800 | E9: UPI | F9: ✅ | G9: Monthly
A10: 46310 | B10: Groceries | C10: 🍽️ Food | D10: 2500 | E10: Cash | F10: ✅ | G10: Weekly
A11: 46313 | B11: Restaurant | C11: 🍽️ Food | D11: 1200 | E11: UPI | F11: ✅ | G11: Dining
A12: 46315 | B12: Clothes | C12: 👕 Shopping | D12: 2000 | E12: Card | F12: ✅ | G12: New shirt
A13: 46317 | B13: Recharge | C13: 📱 Subs | D13: 300 | E13: UPI | F13: ✅ | G13: Monthly
A14: 46320 | B14: Medical | C14: 💊 Health | D14: 800 | E14: Cash | F14: ✅ | G14: Medicines
A15: 46323 | B15: Groceries | C15: 🍽️ Food | D15: 2500 | E15: Cash | F15: ⏳ | G15: Weekly
A16: 46325 | B16: Internet | C16: 💡 Utilities | D16: 350 | E16: Bank | F16: ⏳ | G16: Monthly
A17: TOTAL | D17: =SUM(D4:D16) -> 30450

Sheet Loan_Manager
A1: 🏦 LOAN MANAGER
A3: LOAN | B3: PRINCIPAL | C3: EMI | D3: TENURE | E3: PAID | F3: REMAINING | G3: STATUS
A4: 🎓 Education Loan | B4: 200000 | C4: 5000 | D4: 48 months | E4: 60000 | F4: 140000 | G4: 🟡
A5: 💻 Laptop EMI | B5: 50000 | C5: 2000 | D5: 24 months | E5: 20000 | F5: 30000 | G5: 🟡
A6: 📱 Phone EMI | B6: 30000 | C6: 1500 | D6: 18 months | E6: 15000 | F6: 15000 | G6: 🟡
A7: 🏠 Home Loan | B7: 0 | C7: 0 | D7: — | E7: 0 | F7: 0 | G7: ✅
A10: 🧮 EMI CALCULATOR
A11: Principal: | C11: 100000
A12: Interest Rate (%): | C12: 10
A13: Tenure (Months): | C13: 12
A14: Monthly EMI: | C14: =PMT(C12/100/12,C13,-C11) -> 8791.5887

Sheet Daily_Checklist
A1: ✅ DAILY CHECKLIST
A3: TASK | B3: MON | C3: TUE | D3: WED | E3: THU | F3: FRI | G3: SAT | H3: SUN | I3: %
A4: 🌅 Wake at 6 AM | B4: ☐ | C4: ☐ | D4: ☐ | E4: ☐ | F4: ☐ | G4: ☐ | H4: ☐ | I4: =IFERROR(COUNTIF(B4:H4,"✅")/7,0) -> 0
A5: 💧 1 Glass Water | B5: ☐ | C5: ☐ | D5: ☐ | E5: ☐ | F5: ☐ | G5: ☐ | H5: ☐ | I5: =IFERROR(COUNTIF(B5:H5,"✅")/7,0) -> 0
A6: 💪 Exercise 30 min | B6: ☐ | C6: ☐ | D6: ☐ | E6: ☐ | F6: ☐ | G6: ☐ | H6: ☐ | I6: =IFERROR(COUNTIF(B6:H6,"✅")/7,0) -> 0
A7: 🧘 Meditation 10 min | B7: ☐ | C7: ☐ | D7: ☐ | E7: ☐ | F7: ☐ | G7: ☐ | H7: ☐ | I7: =IFERROR(COUNTIF(B7:H7,"✅")/7,0) -> 0
A8: 📘 Knowledge 1 hr | B8: ☐ | C8: ☐ | D8: ☐ | E8: ☐ | F8: ☐ | G8: ☐ | H8: ☐ | I8: =IFERROR(COUNTIF(B8:H8,"✅")/7,0) -> 0
A9: 🌐 Language 1 hr | B9: ☐ | C9: ☐ | D9: ☐ | E9: ☐ | F9: ☐ | G9: ☐ | H9: ☐ | I9: =IFERROR(COUNTIF(B9:H9,"✅")/7,0) -> 0
A10: 🎓 College Study | B10: ☐ | C10: ☐ | D10: ☐ | E10: ☐ | F10: ☐ | G10: ☐ | H10: ☐ | I10: =IFERROR(COUNTIF(B10:H10,"✅")/7,0) -> 0
A11: 🛠️ Skill Practice | B11: ☐ | C11: ☐ | D11: ☐ | E11: ☐ | F11: ☐ | G11: ☐ | H11: ☐ | I11: =IFERROR(COUNTIF(B11:H11,"✅")/7,0) -> 0
A12: 💼 Office Work | B12: ☐ | C12: ☐ | D12: ☐ | E12: ☐ | F12: ☐ | G12: ☐ | H12: ☐ | I12: =IFERROR(COUNTIF(B12:H12,"✅")/7,0) -> 0
A13: 🍽️ 6 Meals/Day | B13: ☐ | C13: ☐ | D13: ☐ | E13: ☐ | F13: ☐ | G13: ☐ | H13: ☐ | I13: =IFERROR(COUNTIF(B13:H13,"✅")/7,0) -> 0
A14: 💧 8 Glasses Water | B14: ☐ | C14: ☐ | D14: ☐ | E14: ☐ | F14: ☐ | G14: ☐ | H14: ☐ | I14: =IFERROR(COUNTIF(B14:H14,"✅")/7,0) -> 0
A15: 🚶 Walk 30 min | B15: ☐ | C15: ☐ | D15: ☐ | E15: ☐ | F15: ☐ | G15: ☐ | H15: ☐ | I15: =IFERROR(COUNTIF(B15:H15,"✅")/7,0) -> 0
... A21: 📱 No Phone after 9PM | B21: ☐ | C21: ☐ | D21: ☐ | E21: ☐ | F21: ☐ | G21: ☐ | H21: ☐ | I21: =IFERROR(COUNTIF(B21:H21,"✅")/7,0) -> 0

Sheet Hatiya_Market
A1: 🏪 HATIYA MARKET — SHOPPING LIST
A3: ✓ | B3: ITEM | C3: STALL | D3: QTY | E3: PRICE | F3: TOTAL | G3: TIME
A4: ☐ | B4: Tomato | C4: 🥬 Veg Stall | D4: 2 kg | E4: 40 | F4: 80 | G4: 0.41666667
A5: ☐ | B5: Onion | C5: 🥬 Veg Stall | D5: 3 kg | E5: 30 | F5: 90 | G5: 0.42013889
A6: ☐ | B6: Potato | C6: 🥬 Veg Stall | D6: 2 kg | E6: 25 | F6: 50 | G6: 0.42361111
A7: ☐ | B7: Cauliflower | C7: 🥬 Veg Stall | D7: 1 pc | E7: 40 | F7: 40 | G7: 0.42708333
A8: ☐ | B8: Spinach | C8: 🥬 Veg Stall | D8: 500 g | E8: 30 | F8: 30 | G8: 0.43055556
A9: ☐ | B9: Carrot | C9: 🥬 Veg Stall | D9: 500 g | E9: 40 | F9: 40 | G9: 0.43402778
A10: ☐ | B10: Banana | C10: 🍎 Fruit Stall | D10: 1 dozen | E10: 50 | F10: 50 | G10: 0.44444444
A11: ☐ | B11: Apple | C11: 🍎 Fruit Stall | D11: 1 kg | E11: 180 | F11: 180 | G11: 0.44791667
A12: ☐ | B12: Orange | C12: 🍎 Fruit Stall | D12: 1 kg | E12: 80 | F12: 80 | G12: 0.45138889
A13: ☐ | B13: Milk | C13: 🥛 Dairy | D13: 5 L | E13: 60 | F13: 300 | G13: 0.45833333
A14: ☐ | B14: Curd | C14: 🥛 Dairy | D14: 2 kg | E14: 80 | F14: 160 | G14: 0.46180556
A15: ☐ | B15: Paneer | C15: 🥛 Dairy | D15: 500 g | E15: 350 | F15: 350 | G15: 0.46527778
... A24: ☐ | B24: Eggs | C24: 🥚 Egg Stall | D24: 1 dozen | E24: 80 | F24: 80 | G24: 0.5
B25: TOTAL BUDGET | F25: =SUM(F4:F24) -> 3405

Sheet Monthly_Dashboard
A1: 📊 MONTHLY KEY PERFORMANCE INDICATORS
A4: Total Days | C4: Active Days | E4: Completion % | G4: Total Hours | I4: Hours/Day | K4: Knowledge Hrs | M4: Language Hrs | O4: Max Streak
A5: 31 | C5: =IFERROR(COUNTIF(Daily_Tracker!D4:D34,"✅"),0) -> 0 | E5: =IFERROR(C5/B5,0) -> 0 | G5: =IFERROR(SUM(Daily_Tracker!F4:F34),0) -> 0 | I5: =IFERROR(G5/B5,0) -> 0 | K5: =IFERROR(SUM(Daily_Tracker!G4:G34),0) -> 0 | M5: =IFERROR(SUM(Daily_Tracker!H4:H34),0) -> 0 | O5: =IFERROR(MAX(Daily_Tracker!K4:K34),0) -> 0

Sheet Daily_Tracker
A1: 📅 DAILY TRACKER — MONTH
A3: Day | B3: Date | C3: Week | D3: Status | E3: Mood | F3: Total Hrs | G3: Knowledge | H3: Language | I3: Skill | J3: College | K3: Streak
A4: 1 | B4: 46296 | C4: W40 | D4: ☐ | E4: 😐 | F4: 0 | G4: 0 | H4: 0 | I4: 0 | J4: 0 | K4: 0
A5: 2 | B5: 46297 | C5: W40 | D5: ☐ | E5: 😐 | F5: 0 | G5: 0 | H5: 0 | I5: 0 | J5: 0 | K5: 0
A6: 3 | B6: 46298 | C6: W40 | D6: ☐ | E6: 😐 | F6: 0 | G6: 0 | H6: 0 | I6: 0 | J6: 0 | K6: 0
A7: 4 | B7: 46299 | C7: W40 | D7: ☐ | E7: 😐 | F7: 0 | G7: 0 | H7: 0 | I7: 0 | J7: 0 | K7: 0
A8: 5 | B8: 46300 | C8: W41 | D8: ☐ | E8: 😐 | F8: 0 | G8: 0 | H8: 0 | I8: 0 | J8: 0 | K8: 0
A9: 6 | B9: 46301 | C9: W41 | D9: ☐ | E9: 😐 | F9: 0 | G9: 0 | H9: 0 | I9: 0 | J9: 0 | K9: 0
A10: 7 | B10: 46302 | C10: W41 | D10: ☐ | E10: 😐 | F10: 0 | G10: 0 | H10: 0 | I10: 0 | J10: 0 | K10: 0
A11: 8 | B11: 46303 | C11: W41 | D11: ☐ | E11: 😐 | F11: 0 | G11: 0 | H11: 0 | I11: 0 | J11: 0 | K11: 0
A12: 9 | B12: 46304 | C12: W41 | D12: ☐ | E12: 😐 | F12: 0 | G12: 0 | H12: 0 | I12: 0 | J12: 0 | K12: 0
A13: 10 | B13: 46305 | C13: W41 | D13: ☐ | E13: 😐 | F13: 0 | G13: 0 | H13: 0 | I13: 0 | J13: 0 | K13: 0
A14: 11 | B14: 46306 | C14: W41 | D14: ☐ | E14: 😐 | F14: 0 | G14: 0 | H14: 0 | I14: 0 | J14: 0 | K14: 0
A15: 12 | B15: 46307 | C15: W42 | D15: ☐ | E15: 😐 | F15: 0 | G15: 0 | H15: 0 | I15: 0 | J15: 0 | K15: 0
... A34: 31 | B34: 46326 | C34: W44 | D34: ☐ | E34: 😐 | F34: 0 | G34: 0 | H34: 0 | I34: 0 | J34: 0 | K34: 0

Sheet Monthly_Goals
A1: 🎯 MONTHLY GOALS
A3: Category | B3: Goal | C3: Target | D3: Current | E3: % | F3: Deadline | G3: Status
A4: 🎓 College | B4: Complete 5 subjects | C4: 5 | D4: 4 | E4: =IFERROR(D4/C4,0) -> 0.8 | F4: 46326 | G4: =IF(E4>=0.9,"🟢 Done",IF(E4>=0.7,"🟡 Good",IF(E4>0,"🔴 Progress","⚪ Not Started"))) -> 🟡 Good
A5: 📘 Knowledge | B5: Read 4 books | C5: 4 | D5: 2 | E5: =IFERROR(D5/C5,0) -> 0.5 | F5: 46326 | G5: =IF(E5>=0.9,"🟢 Done",IF(E5>=0.7,"🟡 Good",IF(E5>0,"🔴 Progress","⚪ Not Started"))) -> 🔴 Progress
A6: 🌐 Language | B6: Learn 650 words | C6: 650 | D6: 400 | E6: =IFERROR(D6/C6,0) -> 0.61538462 | F6: 46326 | G6: =IF(E6>=0.9,"🟢 Done",IF(E6>=0.7,"🟡 Good",IF(E6>0,"🔴 Progress","⚪ Not Started"))) -> 🔴 Progress
A7: 🛠️ Skill | B7: Build 3 projects | C7: 3 | D7: 1 | E7: =IFERROR(D7/C7,0) -> 0.33333333 | F7: 46326 | G7: =IF(E7>=0.9,"🟢 Done",IF(E7>=0.7,"🟡 Good",IF(E7>0,"🔴 Progress","⚪ Not Started"))) -> 🔴 Progress
A8: 📊 Excel | B8: 40 tasks | C8: 40 | D8: 20 | E8: =IFERROR(D8/C8,0) -> 0.5 | F8: 46326 | G8: =IF(E8>=0.9,"🟢 Done",IF(E8>=0.7,"🟡 Good",IF(E8>0,"🔴 Progress","⚪ Not Started"))) -> 🔴 Progress
A9: 🗄️ SQL | B9: 80 queries | C9: 80 | D9: 45 | E9: =IFERROR(D9/C9,0) -> 0.5625 | F9: 46326 | G9: =IF(E9>=0.9,"🟢 Done",IF(E9>=0.7,"🟡 Good",IF(E9>0,"🔴 Progress","⚪ Not Started"))) -> 🔴 Progress
A10: 🐍 Python | B10: 20 topics | C10: 20 | D10: 12 | E10: =IFERROR(D10/C10,0) -> 0.6 | F10: 46326 | G10: =IF(E10>=0.9,"🟢 Done",IF(E10>=0.7,"🟡 Good",IF(E10>0,"🔴 Progress","⚪ Not Started"))) -> 🔴 Progress
A11: 🧮 DSA | B11: 40 problems | C11: 40 | D11: 22 | E11: =IFERROR(D11/C11,0) -> 0.55 | F11: 46326 | G11: =IF(E11>=0.9,"🟢 Done",IF(E11>=0.7,"🟡 Good",IF(E11>0,"🔴 Progress","⚪ Not Started"))) -> 🔴 Progress
A12: 💪 Health | B12: Gain 2 kg | C12: 2 | D12: 1 | E12: =IFERROR(D12/C12,0) -> 0.5 | F12: 46326 | G12: =IF(E12>=0.9,"🟢 Done",IF(E12>=0.7,"🟡 Good",IF(E12>0,"🔴 Progress","⚪ Not Started"))) -> 🔴 Progress
A13: 💰 Finance | B13: Save ₹22,000 | C13: 22000 | D13: 12000 | E13: =IFERROR(D13/C13,0) -> 0.54545455 | F13: 46326 | G13: =IF(E13>=0.9,"🟢 Done",IF(E13>=0.7,"🟡 Good",IF(E13>0,"🔴 Progress","⚪ Not Started"))) -> 🔴 Progress
A14: 🏆 Marketing | B14: 4 milestones | C14: 4 | D14: 2 | E14: =IFERROR(D14/C14,0) -> 0.5 | F14: 46326 | G14: =IF(E14>=0.9,"🟢 Done",IF(E14>=0.7,"🟡 Good",IF(E14>0,"🔴 Progress","⚪ Not Started"))) -> 🔴 Progress
A15: 🔥 Habit | B15: 31-day streak | C15: 31 | D15: 18 | E15: =IFERROR(D15/C15,0) -> 0.58064516 | F15: 46326 | G15: =IF(E15>=0.9,"🟢 Done",IF(E15>=0.7,"🟡 Good",IF(E15>0,"🔴 Progress","⚪ Not Started"))) -> 🔴 Progress
... A17: 📚 Reading | B17: 30 min daily | C17: 31 | D17: 18 | E17: =IFERROR(D17/C17,0) -> 0.58064516 | F17: 46326 | G17: =IF(E17>=0.9,"🟢 Done",IF(E17>=0.7,"🟡 Good",IF(E17>0,"🔴 Progress","⚪ Not Started"))) -> 🔴 Progress

Sheet Monthly_Habits
A1: 🔥 MONTHLY HABITS TRACKER
A3: HABIT | B3: 1 | C3: 2 | D3: 3 | E3: 4 | F3: 5 | G3: 6 | H3: 7 | I3: 8 | J3: 9 | K3: 10 | L3: 11 | M3: 12 | N3: 13 | O3: 14 | P3: 15 | Q3: 16 | R3: 17 | S3: 18 | T3: 19 | U3: 20 | V3: 21 | W3: 22 | X3: 23 | Y3: 24 | Z3: 25 | AA3: 26 | AB3: 27 | AC3: 28 | AD3: 29 | AE3: 30 | AF3: 31 | AG3: TOTAL
A4: 🌅 Wake 6 AM | B4: ☐ | C4: ☐ | D4: ☐ | E4: ☐ | F4: ☐ | G4: ☐ | H4: ☐ | I4: ☐ | J4: ☐ | K4: ☐ | L4: ☐ | M4: ☐ | N4: ☐ | O4: ☐ | P4: ☐ | Q4: ☐ | R4: ☐ | S4: ☐ | T4: ☐ | U4: ☐ | V4: ☐ | W4: ☐ | X4: ☐ | Y4: ☐ | Z4: ☐ | AA4: ☐ | AB4: ☐ | AC4: ☐ | AD4: ☐ | AE4: ☐ | AF4: ☐ | AG4: =COUNTIF(B4:AF4,"✅") -> 0
A5: 💪 Exercise | B5: ☐ | C5: ☐ | D5: ☐ | E5: ☐ | F5: ☐ | G5: ☐ | H5: ☐ | I5: ☐ | J5: ☐ | K5: ☐ | L5: ☐ | M5: ☐ | N5: ☐ | O5: ☐ | P5: ☐ | Q5: ☐ | R5: ☐ | S5: ☐ | T5: ☐ | U5: ☐ | V5: ☐ | W5: ☐ | X5: ☐ | Y5: ☐ | Z5: ☐ | AA5: ☐ | AB5: ☐ | AC5: ☐ | AD5: ☐ | AE5: ☐ | AF5: ☐ | AG5: =COUNTIF(B5:AF5,"✅") -> 0
A6: 📘 Knowledge | B6: ☐ | C6: ☐ | D6: ☐ | E6: ☐ | F6: ☐ | G6: ☐ | H6: ☐ | I6: ☐ | J6: ☐ | K6: ☐ | L6: ☐ | M6: ☐ | N6: ☐ | O6: ☐ | P6: ☐ | Q6: ☐ | R6: ☐ | S6: ☐ | T6: ☐ | U6: ☐ | V6: ☐ | W6: ☐ | X6: ☐ | Y6: ☐ | Z6: ☐ | AA6: ☐ | AB6: ☐ | AC6: ☐ | AD6: ☐ | AE6: ☐ | AF6: ☐ | AG6: =COUNTIF(B6:AF6,"✅") -> 0
A7: 🌐 Language | B7: ☐ | C7: ☐ | D7: ☐ | E7: ☐ | F7: ☐ | G7: ☐ | H7: ☐ | I7: ☐ | J7: ☐ | K7: ☐ | L7: ☐ | M7: ☐ | N7: ☐ | O7: ☐ | P7: ☐ | Q7: ☐ | R7: ☐ | S7: ☐ | T7: ☐ | U7: ☐ | V7: ☐ | W7: ☐ | X7: ☐ | Y7: ☐ | Z7: ☐ | AA7: ☐ | AB7: ☐ | AC7: ☐ | AD7: ☐ | AE7: ☐ | AF7: ☐ | AG7: =COUNTIF(B7:AF7,"✅") -> 0
A8: 🎓 College | B8: ☐ | C8: ☐ | D8: ☐ | E8: ☐ | F8: ☐ | G8: ☐ | H8: ☐ | I8: ☐ | J8: ☐ | K8: ☐ | L8: ☐ | M8: ☐ | N8: ☐ | O8: ☐ | P8: ☐ | Q8: ☐ | R8: ☐ | S8: ☐ | T8: ☐ | U8: ☐ | V8: ☐ | W8: ☐ | X8: ☐ | Y8: ☐ | Z8: ☐ | AA8: ☐ | AB8: ☐ | AC8: ☐ | AD8: ☐ | AE8: ☐ | AF8: ☐ | AG8: =COUNTIF(B8:AF8,"✅") -> 0
A9: 🛠️ Skill | B9: ☐ | C9: ☐ | D9: ☐ | E9: ☐ | F9: ☐ | G9: ☐ | H9: ☐ | I9: ☐ | J9: ☐ | K9: ☐ | L9: ☐ | M9: ☐ | N9: ☐ | O9: ☐ | P9: ☐ | Q9: ☐ | R9: ☐ | S9: ☐ | T9: ☐ | U9: ☐ | V9: ☐ | W9: ☐ | X9: ☐ | Y9: ☐ | Z9: ☐ | AA9: ☐ | AB9: ☐ | AC9: ☐ | AD9: ☐ | AE9: ☐ | AF9: ☐ | AG9: =COUNTIF(B9:AF9,"✅") -> 0
A10: 💼 Office | B10: ☐ | C10: ☐ | D10: ☐ | E10: ☐ | F10: ☐ | G10: ☐ | H10: ☐ | I10: ☐ | J10: ☐ | K10: ☐ | L10: ☐ | M10: ☐ | N10: ☐ | O10: ☐ | P10: ☐ | Q10: ☐ | R10: ☐ | S10: ☐ | T10: ☐ | U10: ☐ | V10: ☐ | W10: ☐ | X10: ☐ | Y10: ☐ | Z10: ☐ | AA10: ☐ | AB10: ☐ | AC10: ☐ | AD10: ☐ | AE10: ☐ | AF10: ☐ | AG10: =COUNTIF(B10:AF10,"✅") -> 0
A11: 📝 Journal | B11: ☐ | C11: ☐ | D11: ☐ | E11: ☐ | F11: ☐ | G11: ☐ | H11: ☐ | I11: ☐ | J11: ☐ | K11: ☐ | L11: ☐ | M11: ☐ | N11: ☐ | O11: ☐ | P11: ☐ | Q11: ☐ | R11: ☐ | S11: ☐ | T11: ☐ | U11: ☐ | V11: ☐ | W11: ☐ | X11: ☐ | Y11: ☐ | Z11: ☐ | AA11: ☐ | AB11: ☐ | AC11: ☐ | AD11: ☐ | AE11: ☐ | AF11: ☐ | AG11: =COUNTIF(B11:AF11,"✅") -> 0
A12: 💧 Water | B12: ☐ | C12: ☐ | D12: ☐ | E12: ☐ | F12: ☐ | G12: ☐ | H12: ☐ | I12: ☐ | J12: ☐ | K12: ☐ | L12: ☐ | M12: ☐ | N12: ☐ | O12: ☐ | P12: ☐ | Q12: ☐ | R12: ☐ | S12: ☐ | T12: ☐ | U12: ☐ | V12: ☐ | W12: ☐ | X12: ☐ | Y12: ☐ | Z12: ☐ | AA12: ☐ | AB12: ☐ | AC12: ☐ | AD12: ☐ | AE12: ☐ | AF12: ☐ | AG12: =COUNTIF(B12:AF12,"✅") -> 0
A13: 😴 Sleep 10PM | B13: ☐ | C13: ☐ | D13: ☐ | E13: ☐ | F13: ☐ | G13: ☐ | H13: ☐ | I13: ☐ | J13: ☐ | K13: ☐ | L13: ☐ | M13: ☐ | N13: ☐ | O13: ☐ | P13: ☐ | Q13: ☐ | R13: ☐ | S13: ☐ | T13: ☐ | U13: ☐ | V13: ☐ | W13: ☐ | X13: ☐ | Y13: ☐ | Z13: ☐ | AA13: ☐ | AB13: ☐ | AC13: ☐ | AD13: ☐ | AE13: ☐ | AF13: ☐ | AG13: =COUNTIF(B13:AF13,"✅") -> 0
A14: 📵 No Phone | B14: ☐ | C14: ☐ | D14: ☐ | E14: ☐ | F14: ☐ | G14: ☐ | H14: ☐ | I14: ☐ | J14: ☐ | K14: ☐ | L14: ☐ | M14: ☐ | N14: ☐ | O14: ☐ | P14: ☐ | Q14: ☐ | R14: ☐ | S14: ☐ | T14: ☐ | U14: ☐ | V14: ☐ | W14: ☐ | X14: ☐ | Y14: ☐ | Z14: ☐ | AA14: ☐ | AB14: ☐ | AC14: ☐ | AD14: ☐ | AE14: ☐ | AF14: ☐ | AG14: =COUNTIF(B14:AF14,"✅") -> 0
A15: 🧘 Meditation | B15: ☐ | C15: ☐ | D15: ☐ | E15: ☐ | F15: ☐ | G15: ☐ | H15: ☐ | I15: ☐ | J15: ☐ | K15: ☐ | L15: ☐ | M15: ☐ | N15: ☐ | O15: ☐ | P15: ☐ | Q15: ☐ | R15: ☐ | S15: ☐ | T15: ☐ | U15: ☐ | V15: ☐ | W15: ☐ | X15: ☐ | Y15: ☐ | Z15: ☐ | AA15: ☐ | AB15: ☐ | AC15: ☐ | AD15: ☐ | AE15: ☐ | AF15: ☐ | AG15: =COUNTIF(B15:AF15,"✅") -> 0
... A20: 💰 Expenses | B20: ☐ | C20: ☐ | D20: ☐ | E20: ☐ | F20: ☐ | G20: ☐ | H20: ☐ | I20: ☐ | J20: ☐ | K20: ☐ | L20: ☐ | M20: ☐ | N20: ☐ | O20: ☐ | P20: ☐ | Q20: ☐ | R20: ☐ | S20: ☐ | T20: ☐ | U20: ☐ | V20: ☐ | W20: ☐ | X20: ☐ | Y20: ☐ | Z20: ☐ | AA20: ☐ | AB20: ☐ | AC20: ☐ | AD20: ☐ | AE20: ☐ | AF20: ☐ | AG20: =COUNTIF(B20:AF20,"✅") -> 0

Sheet Revision_Schedule
A1: 📚 REVISION SCHEDULE
A3: TIME | B3: MON | C3: TUE | D3: WED | E3: THU | F3: FRI | G3: SAT | H3: SUN | I3: HOURS | J3: TYPE
A4: 0.3125 | B4: 📘 Knowledge | C4: 📘 Knowledge | D4: 📘 Knowledge | E4: 📘 Knowledge | F4: 📘 Knowledge | G4: 📘 Knowledge | H4: 📊 Test | I4: 0.5 | J4: Knowledge
A5: 0.54166667 | B5: 🔄 College | C5: 🔄 College | D5: 🔄 College | E5: 🔄 College | F5: 🔄 College | G5: 🔄 College | H5: 🔄 Mistake | I5: 1 | J5: College
A6: 0.58333333 | B6: 🎓 Stats | C6: 🌐 English | D6: 🛠️ Python | E6: 🌐 Japanese | F6: 🧠 DSA | G6: 🛠️ Excel | H6: 📝 Notes | I6: 0.5 | J6: Mixed
